Workbook

Sheet 종합
B1: 격투가 종합 계산기 v2.3 -시즌1 | H1: 이 색상의 셀만 조작해주세요.
F2: 46115 | G2: 무쇠손/라사 | N2: 현재셋팅 | O2: 셋팅1 | P2: 셋팅2 | Q2: 셋팅3
A3: 조건 | B3: 전투시간 | C3: 120 | D3: 초 | E3: 함선 허수아비 | F3: 방어도계수 | G3: =LET(x, IFS(OR(E3="글라스기브넨", E3="화이트서큐버스"), 6410,E3="허수아비", 30, E3="함선 허수아비", 30, E3="어비스 지옥2", 9153, E3="바리어비스", 15903), 1/(1+x/10328)) -> 0.99710369 | H3: 충전획득량(초당) | I3: 5 | M3: =B11 -> 무기 | N3: =C11 -> 망각+
B4: 무빙시간 | C4: 0 | D4: 초 | E4: 예상되는 기믹으로 인한 무빙시간 | G4: =C4/C3 -> 0 | I4: 기본수치 | J4: 증가수치 | K4: 적용수치 | M4: =B12 -> 장신구1 | N4: =C12 -> 약점
B5: 궁극기횟수 | C5: 2 | D5: =TEXT(((C3-40)/100*K24)*K39+C3*'펫'!E3*K24, "0.00") & " 번 예상(+궁비궁)" -> 0.60 번 예상(+궁비궁) | F5: 궁극기를 사용할 횟수를 입력합니다. | H5: 공격력 | I5: 27166 | J5: =SUMIF('무기룬'!B:B, TRUE, OFFSET('무기룬'!$A:$A, 0, ROW()-2)) + SUMIF('방어구룬'!B:B, TRUE, OFFSET('방어구룬'!$A:$A, 0, ROW()-2)) + SUMIF('엠블럼룬'!B:B, TRUE, OFFSET('엠블럼룬'!$A:$A, 0, ROW()-2))+C10/100 -> 0.418 | K5: =I5*(1+J5) -> 38521.388 | M5: =B13 -> 장신구2 | N5: =C13 -> 전진
B6: 무방비시간 | C6: 0 | D6: 초 | E6: 예상되는 보스몹의 브레이크시간입니다. | H6: 조건부공증 | J6: =SUMIF('무기룬'!B:B, TRUE, OFFSET('무기룬'!$A:$A, 0, ROW()-2)) + SUMIF('방어구룬'!B:B, TRUE, OFFSET('방어구룬'!$A:$A, 0, ROW()-2)) + SUMIF('엠블럼룬'!B:B, TRUE, OFFSET('엠블럼룬'!$A:$A, 0, ROW()-2))+IF(COUNTIF(C12:C14, "비생고(임시)") > 0, 0.25, 0) -> 0.34166667 | K6: =I5*(1+J5+J6) -> 47803.105 | M6: =B14 -> 장신구3 | N6: =C14 -> 강격
B7: 기믹피증 | C7: 0 | D7: % | E7: 이명, 부채꼴, 바닥등등의 피증의 평균입니다. | H7: 주는피해증가 | I7: =G28+C7/100 -> 0 | J7: =SUMIF('무기룬'!B:B, TRUE, OFFSET('무기룬'!$A:$A, 0, ROW()-2)) + SUMIF('방어구룬'!B:B, TRUE, OFFSET('방어구룬'!$A:$A, 0, ROW()-2)) + SUMIF('엠블럼룬'!B:B, TRUE, OFFSET('엠블럼룬'!$A:$A, 0, ROW()-2)) -> 0.07 | K7: =I7+J7 -> 0.07 | M7: =B15 -> 엠블럼 | N7: =C15 -> 아득한 빛
B8: 힐러계열 피증 | C8: 0 | D8: % | E8: 힐러계열의 효과를 받는다면 입력해주세요. | H8: 받는피해증가 | I8: =C9/100 -> 0.1 | J8: =SUMIF('무기룬'!B:B, TRUE, OFFSET('무기룬'!$A:$A, 0, ROW()-2)) + SUMIF('방어구룬'!B:B, TRUE, OFFSET('방어구룬'!$A:$A, 0, ROW()-2)) + SUMIF('엠블럼룬'!B:B, TRUE, OFFSET('엠블럼룬'!$A:$A, 0, ROW()-2)) -> 0 | K8: =I8+J8 -> 0.1 | M8: =E11 -> 방어구1 | N8: =F11 -> 압도적인 힘
B9: 룬, 스킬받피증 | C9: 10 | D9: % | E9: 방어구파괴(최대 10퍼 심찌,차징피스트등등) | H9: 강타피해증가 | I9: =C18/8500 -> 0.29258824 | J9: =SUMIF('무기룬'!B:B, TRUE, OFFSET('무기룬'!$A:$A, 0, ROW()-2)) + SUMIF('방어구룬'!B:B, TRUE, OFFSET('방어구룬'!$A:$A, 0, ROW()-2)) + SUMIF('엠블럼룬'!B:B, TRUE, OFFSET('엠블럼룬'!$A:$A, 0, ROW()-2))+'펫'!H3 -> 0.08 | K9: =I9*(1+J9)+J9 -> 0.39599529 | M9: =E12 -> 방어구2 | N9: =F12 -> 섬세한 손놀림
B10: 인챈트 공증(%) | C10: 6.8 | D10: 강타피해(%) | E10: 1 | F10: 연타피해(%) | H10: 연타피해증가 | I10: =C24/8500 -> 0.35164706 | J10: =SUMIF('무기룬'!B:B, TRUE, OFFSET('무기룬'!$A:$A, 0, ROW()-2)) + SUMIF('방어구룬'!B:B, TRUE, OFFSET('방어구룬'!$A:$A, 0, ROW()-2)) + SUMIF('엠블럼룬'!B:B, TRUE, OFFSET('엠블럼룬'!$A:$A, 0, ROW()-2)) -> 0.206 | K10: =I10*(1+J10)+J10 -> 0.63008635 | M10: =E13 -> 방어구3 | N10: =F13 -> 일렁이는 불꽃
A11: 룬 | B11: 무기 | C11: 망각+ | D11: 초월++ | E11: 방어구1 | F11: 압도적인 힘 | G11: 초월++ | H11: 추가타피해 | I11: 2 | J11: =SUMIF('무기룬'!B:B, TRUE, OFFSET('무기룬'!$A:$A, 0, ROW()-2)) + SUMIF('방어구룬'!B:B, TRUE, OFFSET('방어구룬'!$A:$A, 0, ROW()-2)) + SUMIF('엠블럼룬'!B:B, TRUE, OFFSET('엠블럼룬'!$A:$A, 0, ROW()-2)) -> 0 | K11: =I11++J11 -> 2 | M11: =E14 -> 방어구4 | N11: =F14 -> 바스러지는 빛
B12: 장신구1 | C12: 약점 | D12: 초월+ | E12: 방어구2 | F12: 섬세한 손놀림 | G12: 초월++ | H12: 치명타피해 | I12: =1.4+(C27/5000) -> 2.785 | J12: =SUMIF('무기룬'!B:B, TRUE, OFFSET('무기룬'!$A:$A, 0, ROW()-2)) + SUMIF('방어구룬'!B:B, TRUE, OFFSET('방어구룬'!$A:$A, 0, ROW()-2)) + SUMIF('엠블럼룬'!B:B, TRUE, OFFSET('엠블럼룬'!$A:$A, 0, ROW()-2)) -> 0.30666667 | K12: =I12*(1+J12) -> 3.6390667 | M12: =E15 -> 방어구5 | N12: =F15 -> 산들바람 | R12: 무기~치명타까지 복사됩니다.
B13: 장신구2 | C13: 전진 | D13: 초월+ | E13: 방어구3 | F13: 일렁이는 불꽃 | G13: 초월+ | H13: 콤보피해증가 | I13: =C19/17500 -> 0.087542857 | J13: =SUMIF('무기룬'!B:B, TRUE, OFFSET('무기룬'!$A:$A, 0, ROW()-2)) + SUMIF('방어구룬'!B:B, TRUE, OFFSET('방어구룬'!$A:$A, 0, ROW()-2)) + SUMIF('엠블럼룬'!B:B, TRUE, OFFSET('엠블럼룬'!$A:$A, 0, ROW()-2)) -> 0 | K13: =((1+I13)*(1+J13)-1)*(K37/4) -> 0.046988372 | L13: 평균치 | M13: 기본공격력 | N13: =I5 -> 27166
B14: 장신구3 | C14: 강격 | D14: 초월+ | E14: 방어구4 | F14: 바스러지는 빛 | G14: 일반 | H14: 멀티피해증가 | I14: =0.08+(C21/8500) -> 0.20729412 | J14: =SUMIF('무기룬'!B:B, TRUE, OFFSET('무기룬'!$A:$A, 0, ROW()-2)) + SUMIF('방어구룬'!B:B, TRUE, OFFSET('방어구룬'!$A:$A, 0, ROW()-2)) + SUMIF('엠블럼룬'!B:B, TRUE, OFFSET('엠블럼룬'!$A:$A, 0, ROW()-2)) -> 0 | K14: =I14*(1+J14)+J14 -> 0.20729412 | L14: 어비스에서 유효 | M14: =B17 -> 브레이크 | N14: =C17 -> 1742
B15: 엠블럼 | C15: 아득한 빛 | D15: 초월++ | E15: 방어구5 | F15: 산들바람 | G15: 초월+ | H15: 스킬피해증가 | I15: =C20/8500 -> 0.18552941 | J15: =SUMIF('무기룬'!B:B, TRUE, OFFSET('무기룬'!$A:$A, 0, ROW()-2)) + SUMIF('방어구룬'!B:B, TRUE, OFFSET('방어구룬'!$A:$A, 0, ROW()-2)) + SUMIF('엠블럼룬'!B:B, TRUE, OFFSET('엠블럼룬'!$A:$A, 0, ROW()-2)) -> 0 | K15: =I15*(1+J15)+J15 -> 0.18552941 | M15: =B18 -> 강타강화 | N15: =C18 -> 2487
A16: 스텟 | B16: 공격력 | C16: 38521 | D16: 마을공격력을 입력해주세요>>>>>> | F16: I5에 입력>>> | G16: =C16/(1+J5) -> 27165.726 | H16: 추가타확률 | I16: =C22/13000 -> 0.075923077 | J16: =SUMIF('무기룬'!B:B, TRUE, OFFSET('무기룬'!$A:$A, 0, ROW()-2)) + SUMIF('방어구룬'!B:B, TRUE, OFFSET('방어구룬'!$A:$A, 0, ROW()-2)) + SUMIF('엠블럼룬'!B:B, TRUE, OFFSET('엠블럼룬'!$A:$A, 0, ROW()-2)) -> 0.22083333 | K16: =(1+I16)*(1+J16)-1 -> 0.31352276 | M16: =B19 -> 콤보강화 | N16: =C19 -> 1532
B17: 브레이크 | C17: 1742 | D17: 브레이크시 데미지가 증가합니다. | G17: 공증에 가려진 기본공격력입니다. | H17: 치명타확률 | I17: =0.5*(C27/(C27+2000))+if(E3="허수아비",0.3,0) -> 0.38795518 | J17: =SUMIF('무기룬'!B:B, TRUE, OFFSET('무기룬'!$A:$A, 0, ROW()-2)) + SUMIF('방어구룬'!B:B, TRUE, OFFSET('방어구룬'!$A:$A, 0, ROW()-2)) + SUMIF('엠블럼룬'!B:B, TRUE, OFFSET('엠블럼룬'!$A:$A, 0, ROW()-2)) -> 0.17 | K17: =min(1,I17+J17) -> 0.55795518 | M17: =B20 -> 스킬위력 | N17: =C20 -> 1577
B18: 강타강화 | C18: 2487 | D18: 강타 데미지가 증가합니다.(연타와합연산) | G18: 처음한번만 하면됩니다 단, | H18: 캐스팅속도 | I18: 0 | J18: =SUMIF('무기룬'!B:B, TRUE, OFFSET('무기룬'!$A:$A, 0, ROW()-2)) + SUMIF('방어구룬'!B:B, TRUE, OFFSET('방어구룬'!$A:$A, 0, ROW()-2)) + SUMIF('엠블럼룬'!B:B, TRUE, OFFSET('엠블럼룬'!$A:$A, 0, ROW()-2)) -> 0 | K18: =I18+J18 -> 0 | M18: =B21 -> 광역강화 | N18: =C21 -> 1082
B19: 콤보강화 | C19: 1532 | D19: 콤보 데미지가 증가합니다. | G19: 6,7성룬 섞이면 다시하세요 | H19: 무방비피해증가 | I19: =C17/5250 -> 0.33180952 | J19: =SUMIF('무기룬'!B:B, TRUE, OFFSET('무기룬'!$A:$A, 0, ROW()-2)) + SUMIF('방어구룬'!B:B, TRUE, OFFSET('방어구룬'!$A:$A, 0, ROW()-2)) + SUMIF('엠블럼룬'!B:B, TRUE, OFFSET('엠블럼룬'!$A:$A, 0, ROW()-2))+'펫'!F3 -> 0 | K19: =(1+J19)*(1+I19)+0.4-1 -> 0.73180952 | M19: =B22 -> 추가타 | N19: =C22 -> 987
B20: 스킬위력 | C20: 1577 | D20: 스킬피해증가 수치가 증가합니다. | G20: 수치를 모른다면 | H20: 회복속도증가 | I20: 0 | J20: =SUMIF('무기룬'!B:B, TRUE, OFFSET('무기룬'!$A:$A, 0, ROW()-2)) + SUMIF('방어구룬'!B:B, TRUE, OFFSET('방어구룬'!$A:$A, 0, ROW()-2)) + SUMIF('엠블럼룬'!B:B, TRUE, OFFSET('엠블럼룬'!$A:$A, 0, ROW()-2)) -> 0 | K20: =I20+J20 -> 0 | M20: =B23 -> 빠른공격 | N20: =C23 -> 1484
B21: 광역강화 | C21: 1082 | D21: 멀티피해 데미지가 증가합니다. | G21: '공격력변환'시트로 | H21: 스킬속도증가 | I21: =C25*'스킬 및 딜사이클'!A27 -> 0.10416 | J21: =SUMIF('무기룬'!B:B, TRUE, OFFSET('무기룬'!$A:$A, 0, ROW()-2)) + SUMIF('방어구룬'!B:B, TRUE, OFFSET('방어구룬'!$A:$A, 0, ROW()-2)) + SUMIF('엠블럼룬'!B:B, TRUE, OFFSET('엠블럼룬'!$A:$A, 0, ROW()-2))+'펫'!G3 -> 0 | K21: =I21+J21 -> 0.10416 | M21: =B24 -> 연타강화 | N21: =C24 -> 2989
B22: 추가타 | C22: 987 | D22: 추가타 확률이 증가합니다. | H22: 공격속도증가 | I22: =C23*0.00007 -> 0.10388 | J22: =SUMIF('무기룬'!B:B, TRUE, OFFSET('무기룬'!$A:$A, 0, ROW()-2)) + SUMIF('방어구룬'!B:B, TRUE, OFFSET('방어구룬'!$A:$A, 0, ROW()-2)) + SUMIF('엠블럼룬'!B:B, TRUE, OFFSET('엠블럼룬'!$A:$A, 0, ROW()-2))+'펫'!G3 -> 0 | K22: =I22+J22 -> 0.10388 | M22: =B25 -> 빠른스킬 | N22: =C25 -> 1488
B23: 빠른공격 | C23: 1484 | D23: 평타사용시간이 줄어듭니다. | H23: 기본공격추가타 | I23: 0 | J23: =SUMIF('무기룬'!B:B, TRUE, OFFSET('무기룬'!$A:$A, 0, ROW()-2)) + SUMIF('방어구룬'!B:B, TRUE, OFFSET('방어구룬'!$A:$A, 0, ROW()-2)) + SUMIF('엠블럼룬'!B:B, TRUE, OFFSET('엠블럼룬'!$A:$A, 0, ROW()-2)) -> 0 | K23: =I23+J23 -> 0 | M23: =B27 -> 치명타 | N23: =C27 -> 6925
B24: 연타강화 | C24: 2989 | D24: 연타 데미지가 증가합니다.(강타와합연산) | H24: 궁극기획득량 | I24: =C26/7250+1 -> 1.2471724 | J24: =SUMIF('무기룬'!B:B, TRUE, OFFSET('무기룬'!$A:$A, 0, ROW()-2)) + SUMIF('방어구룬'!B:B, TRUE, OFFSET('방어구룬'!$A:$A, 0, ROW()-2)) + SUMIF('엠블럼룬'!B:B, TRUE, OFFSET('엠블럼룬'!$A:$A, 0, ROW()-2)) -> 0 | K24: =I24*(1+J24) -> 1.2471724 | M24: 전투시간 | N24: =C3&"초"&"" -> 120초
B25: 빠른스킬 | C25: 1488 | D25: 스킬사용시간이 줄어듭니다. | H25: 직접피해(초당계수) | I25: 0 | J25: =SUMIF('무기룬'!B:B, TRUE, OFFSET('무기룬'!$A:$A, 0, ROW()-2)) + SUMIF('방어구룬'!B:B, TRUE, OFFSET('방어구룬'!$A:$A, 0, ROW()-2)) + SUMIF('엠블럼룬'!B:B, TRUE, OFFSET('엠블럼룬'!$A:$A, 0, ROW()-2)) -> 0 | K25: =I25+J25 -> 0 | M25: 딜사이클 | N25: =C37 -> 2352 12
B26: 궁극기 | C26: 1792 | D26: 궁극기스택이 획득량이 증가합니다 | H26: 지속피해(초당계수) | I26: 0 | J26: =SUMIF('무기룬'!B:B, TRUE, OFFSET('무기룬'!$A:$A, 0, ROW()-2)) + SUMIF('방어구룬'!B:B, TRUE, OFFSET('방어구룬'!$A:$A, 0, ROW()-2)) + SUMIF('엠블럼룬'!B:B, TRUE, OFFSET('엠블럼룬'!$A:$A, 0, ROW()-2)) -> 0 | K26: =I26+J26 -> 0 | M26: 무방비시간 | N26: =C6&"초" -> 0초
B27: 치명타 | C27: 6925 | D27: 치명타 확률 및 피해가 증가합니다. | H27: 이동속도 | I27: 4 | J27: =SUMIF('무기룬'!B:B, TRUE, OFFSET('무기룬'!$A:$A, 0, ROW()-2)) + SUMIF('방어구룬'!B:B, TRUE, OFFSET('방어구룬'!$A:$A, 0, ROW()-2)) + SUMIF('엠블럼룬'!B:B, TRUE, OFFSET('엠블럼룬'!$A:$A, 0, ROW()-2)) -> 0 | K27: =I27*(1+J27) -> 4 | M27: 딜사이클 | N27: =E37 -> 2352 12
A28: 세공 | B28: 강타 뎀증 | C28: ='보석'!F25 -> 0.471 | D28: 강타 쿨감 | E28: ='보석'!N25 -> 0.0285 | F28: 헬리오도르 | G28: ='보석'!B25 -> 0 | H28: 특이사항 | M28: 궁극기시간 | N28: =G38+I38&"초" -> 33초
B29: 이동 뎀증 | C29: ='보석'!H25 -> 0.471 | D29: 이동 쿨감 | E29: ='보석'!P25 -> 0.0425 | F29: 그린 헬리오도르 | G29: ='보석'!C25 -> 0 | H29: =IFERROR(__xludf.DUMMYFUNCTION("IFNA(WRAPROWS(LET( stacked_data, {{'무기룬'!B:B, '무기룬'!AA:AA}; {'방어구룬'!B:B, '방어구룬'!AA:AA}; {'엠블럼룬'!B:B, '엠블럼룬'!AA:AA}}, FILTER( CHOOSECOLS(stacked_data, 2), (CHOOSECOLS(stacked_data, 1) = TRUE) * (CHOOSECOLS(stacked_"&"data, 2) <> """") ) ), 4), """")"),"평타쿨감9%") -> 평타쿨감9% | I29: =IFERROR(__xludf.DUMMYFUNCTION("""COMPUTED_VALUE"""),"각성종속") -> 각성종속 | J29: =IFERROR(__xludf.DUMMYFUNCTION("""COMPUTED_VALUE"""),"각성종속") -> 각성종속 | K29: =IFERROR(__xludf.DUMMYFUNCTION("""COMPUTED_VALUE"""),"방어구룬에서 강화입력") -> 방어구룬에서 강화입력 | M29: 딜사이클 | N29: =G37 & " / " & I37 -> 252 / 252
B30: 보조 뎀증 | C30: ='보석'!G25 -> 0.021 | D30: 보조 쿨감 | E30: ='보석'!O25 -> 0.0075 | M30: 직접, 지속피해 지분 | N30: =(K42+K43)/K44 -> 0
B31: 방해 뎀증 | C31: ='보석'!E25 -> 0.021 | D31: 방해 쿨감 | E31: ='보석'!M25 -> 0 | M31: 대상 | N31: =E3 -> 함선 허수아비
B32: 생존 뎀증 | C32: ='보석'!D25 -> 0 | D32: 생존 쿨감 | E32: ='보석'!L25 -> 0 | M32: 무빙계수 | N32: =C4/C3 -> 0
A33: 스킬 개조 | B33: 1 | C33: 2 | D33: 3 | E33: 4 | F33: 5 | G33: 6 | M33: 펫 | N33: ='펫'!C3 -> 무옵
B34: 10 | C34: 30 | D34: 10 | E34: 10 | F34: 30 | G34: 30 | M34: 예상 DPS | N34: =K44 -> 3463303.9
A35: 딜사이클 및 DPS | B35: =IF(B34>30, "30초과", IF(SUM(B$34:G$34)>120, "합계 120 초과", "")) | C35: =IF(C34>30, "30초과", IF(SUM(C$34:H$34)>120, "합계 120 초과", "")) | D35: =IF(D34>30, "30초과", IF(SUM(D$34:I$34)>120, "합계 120 초과", "")) | E35: =IF(E34>30, "30초과", IF(SUM(E$34:J$34)>120, "합계 120 초과", "")) | F35: =IF(F34>30, "30초과", IF(SUM(F$34:K$34)>120, "합계 120 초과", "")) | G35: =IF(G34>30, "30초과", IF(SUM(G$34:M$34)>120, "합계 120 초과", "")) | N35: 현재셋팅 저장 | O35: FALSE | P35: FALSE | Q35: FALSE
B36: 평상시 | D36: 평소 무방비시 | F36: 궁극기 사용시 | H36: 무방비 궁극기 사용시 | J36: 합계 | N36: 비교값 | O36: =IFERROR((O34)/$N34-1, "") -> -1 | P36: =IFERROR((P34)/$N34-1, "") -> -1 | Q36: =IFERROR((Q34)/$N34-1, "") -> -1
B37: 딜사이클 | C37: 2352 12 | D37: 딜사이클 | E37: 2352 12 | F37: 딜사이클 | G37: 252 | H37: 콤보강화변수 | I37: 252 | J37: 콤보강화변수 | K37: =LET(x, K39, y, K38, t_11, 11/x, t_51, 51/x, t_101, 101/x, dur_1, MIN(y, t_11), dur_2, MAX(0, MIN(y, t_51) - t_11), dur_3, MAX(0, MIN(y, t_101) - t_51), dur_4, MAX(0, y - t_101), (dur_1*1 + dur_2*2 + dur_3*3 + dur_4*4) / y) -> 2.1469883 | M37: 이 계산기의 목적은 셋팅간 우위를 찾아보기 위한것임 오차범위내라면 허수아비등으로 체크를 다시해보는걸 추천함 반영된것 검무등등 대부분의 축적, 누적룬 가동률, 재사용시간 회복속도룬, 쿨감룬, 갈땅의 추가공격은 추가타피해로 계산함 반영안된것 필사의일격 쿨초기화, ###약점 카운터조건###, 종언의 적처치시 효과 궁극기 dps 반영시 사이클단위가 아님 본인만의 루틴이있으면 그게더좋음 1-2 사거리가 짧아서 드라군처럼 무빙하는것, 종언+ 조건부 공증 궁극기 3초 선딜 주의해야할것 각성과 궁극기 사용을 맞출경우 dps가 계산기보다 더 높게나올수있음 궁쿨감과 세공쿨감 곱연으로 계산함 트리거는 모두 만족한것으로 계산함
B38: 시간(초) | C38: =max(,0,C3-E38-G38-I38) -> 87 | D38: 시간(초) | E38: =C6-I38 -> 0 | F38: 시간(초) | G38: =MIN(C5*'스킬 및 딜사이클'!Y3, C3) * (1-(C6/C3)) -> 33 | H38: 시간(초) | I38: =MIN(C5*'스킬 및 딜사이클'!Y3, C3) * (C6/C3) -> 0 | J38: 시간(초) | K38: =sum(E38,G38,I38,C38) -> 120
B39: 초당스킬횟수 | C39: ='스킬 및 딜사이클'!C32/'스킬 및 딜사이클'!AJ50 -> 0.66379024 | D39: 초당스킬횟수 | E39: ='스킬 및 딜사이클'!C54/'스킬 및 딜사이클'!AJ72 -> 0.66379024 | F39: 초당스킬횟수 | G39: ='스킬 및 딜사이클'!C76/'스킬 및 딜사이클'!AJ94/2 -> 0.4525422 | H39: 초당스킬횟수 | I39: ='스킬 및 딜사이클'!C98/'스킬 및 딜사이클'!AJ116/2 -> 0.4525422 | J39: 초당스킬횟수 | K39: =(C39*C38+E39*E38+G39*G38+I39*I38)/K38 -> 0.60569703
B40: 초당평타횟수 | C40: ='스킬 및 딜사이클'!AJ47/'스킬 및 딜사이클'!AJ50 -> 0.44252683 | D40: 초당평타횟수 | E40: ='스킬 및 딜사이클'!AJ69/'스킬 및 딜사이클'!AJ72 -> 0.44252683 | F40: 초당평타횟수 | G40: ='스킬 및 딜사이클'!AJ91/'스킬 및 딜사이클'!AJ94 -> 0 | H40: 초당평타횟수 | I40: ='스킬 및 딜사이클'!AJ113/'스킬 및 딜사이클'!AJ116 -> 0 | J40: 초당평타횟수 | K40: =(C40*C38+E40*E38+G40*G38+I40*I38)/K38 -> 0.32083195
...

Sheet 펫
N1: 주요 펫 보유효과 및 고유스킬 (전설) | O1: 고유스킬 | P1: 보유효과
B2: 태그 | C2: 그 외 | D2: 쿨감 | E2: 초당궁극기회복 | F2: 무방비데미지증가 | G2: 공속,스속 | H2: 강타데미지증가평균 | N2: 골든 리트리버 | O2: 무옵 | P2: 공584 치1095
B3: 고유스킬 | C3: 무옵 | D3: =COUNTIF(C4:C6, "반사신경")*if(C2="신속",20%,15%) -> 0 | E3: {=IFERROR(XLOOKUP($C$3, $B$13:$B$24, E$13:E$24) / XLOOKUP($C$3, $B$13:$B$24, $K$13:$K$24),0)} -> 0 | F3: {=IFERROR(XLOOKUP($C$3, $B$13:$B$24, F$13:F$24) *IFERROR( MIN(1, 6 / XLOOKUP($C$3, $B$13:$B$24, $K$13:$K$24)), 0),0)} -> 0 | G3: {=IFERROR(XLOOKUP($C$3, $B$13:$B$24, G$13:G$24) *IFERROR( MIN(1, 5 / XLOOKUP($C$3, $B$13:$B$24, $K$13:$K$24)), 0),0)} -> 0 | H3: {=IFERROR(XLOOKUP($C$3, $B$13:$B$24, H$13:H$24) *IFERROR( MIN(1, 10 / XLOOKUP($C$3, $B$13:$B$24, $K$13:$K$24)), 0),0)} -> 0 | N3: 블랙탄 포메라니안 | O3: 궁극의 응원S | P3: 공584 강1095
B4: 일반스킬 | C4: 그 외 | N4: 갈색 포메라니안 | O4: 궁극의 응원SS | P4: 공584 광1095
B5: 일반스킬 | C5: 그 외 | N5: 연회색 라쿤 | O5: 무옵 | P5: 연1095 치1095
B6: 일반스킬 | C6: 그 외 | N6: 까만 아기 늑대 | O6: 브레이크 하울링SS | P6: 공584 스위1095
N7: 흰 아기 올빼미 | O7: 쾌속의 날갯짓SS | P7: 공584 추1095
B8: '펫'시트는 DPS에 유의미한 스킬을 계산하기 위함입니다. 펫이 넘어지는 것은 반영되지않음 (빙결, 화상트리거류 제외) 펫의 동행능력치는 '종합'시트에서 직접 반영하여 입력 하셔야합니다. | N8: 흰 햄스터 | O8: 작은 동반자의 응원S | P8: 연1095 브1095
N9: 골든 햄스터 | O9: 작은 동반자의 응원SS | P9: 스위1095 빠스1095
N10: 연갈색 시추 | O10: 무옵 | P10: 치1095 추1095
K12: 쿨감이후
B13: 궁극의 응원 | C13: 플레이어의 궁극기 게이지 충전 | E13: 0.06 | I13: 40 | J13: 초 | K13: =I13*(1-$D$3) -> 40 | L13: 초
B14: 궁극의 응원S | C14: 플레이어의 궁극기 게이지 충전 | E14: 0.08 | I14: 40 | J14: 초 | K14: =I14*(1-$D$3) -> 40 | L14: 초
B15: 궁극의 응원SS | C15: 플레이어의 궁극기 게이지 충전 | E15: 0.1 | I15: 40 | J15: 초 | K15: =I15*(1-$D$3) -> 40 | L15: 초
B16: 브레이크 하울링 | C16: 6초 동안 무방비 대미지 증가 | F16: 0.02 | I16: 8 | J16: 초 | K16: =I16*(1-$D$3) -> 8 | L16: 초
B17: 브레이크 하울링S | C17: 6초 동안 무방비 대미지 증가 | F17: 0.03 | I17: 8 | J17: 초 | K17: =I17*(1-$D$3) -> 8 | L17: 초
B18: 브레이크 하울링SS | C18: 6초 동안 무방비 대미지 증가 | F18: 0.04 | I18: 8 | J18: 초 | K18: =I18*(1-$D$3) -> 8 | L18: 초
B19: 쾌속의 날갯짓 | C19: 5초 동안 스킬 , 공격속도 증가 | G19: 0.1 | I19: 30 | J19: 초 | K19: =I19*(1-$D$3) -> 30 | L19: 초
B20: 쾌속의 날갯짓S | C20: 5초 동안 스킬 , 공격속도 증가 | G20: 0.12 | I20: 30 | J20: 초 | K20: =I20*(1-$D$3) -> 30 | L20: 초
B21: 쾌속의 날갯짓SS | C21: 5초 동안 스킬 , 공격속도 증가 | G21: 0.15 | I21: 30 | J21: 초 | K21: =I21*(1-$D$3) -> 30 | L21: 초
B22: 작은 동반자의 응원 | C22: 10초동안 강타대미지 증가 | H22: 0.08 | I22: 50 | J22: 초 | K22: =I22*(1-$D$3) -> 50 | L22: 초
B23: 작은 동반자의 응원S | C23: 10초동안 강타대미지 증가 | H23: 0.09 | I23: 50 | J23: 초 | K23: =I23*(1-$D$3) -> 50 | L23: 초
B24: 작은 동반자의 응원SS | C24: 10초동안 강타대미지 증가 | H24: 0.1 | I24: 50 | J24: 초 | K24: =I24*(1-$D$3) -> 50 | L24: 초

Sheet 보석
B1: 헬리오 | C1: 그린헬리 | D1: 생존 뎀증 | E1: 방해 뎀증 | F1: 강타 뎀증 | G1: 보조 뎀증 | H1: 이동 뎀증 | I1: 연타 뎀증 | J1: 소환 뎀증 | K1: 원소 뎀증 | L1: 생존 쿨감 | M1: 방해 쿨감 | N1: 강타 쿨감 | O1: 보조 쿨감 | P1: 이동 쿨감 | Q1: 연타 쿨감 | R1: 소환 쿨감 | S1: 원소 쿨감
A2: 무기 | F2: 2.1 | H2: 2.1 | N2: 0.7 | T2: =IF((IF(B2, 3, 0) + IF(C2, 3, 0) + COUNTA(D2:S2)) > 3, "확인요망", "")
F3: 2.1 | H3: 2.1 | N3: 0.7 | T3: =IF((IF(B3, 3, 0) + IF(C3, 3, 0) + COUNTA(D3:S3)) > 3, "확인요망", "")
F4: 2.1 | H4: 2.1 | N4: 0.7 | T4: =IF((IF(B4, 3, 0) + IF(C4, 3, 0) + COUNTA(D4:S4)) > 3, "확인요망", "")
A5: 목걸이 | F5: 2.2 | H5: 2.2 | N5: 0.75 | T5: =IF((IF(B5, 3, 0) + IF(C5, 3, 0) + COUNTA(D5:S5)) > 3, "확인요망", "")
A6: 반지 | F6: 2.2 | H6: 2.2 | P6: 0.75 | T6: =IF((IF(B6, 3, 0) + IF(C6, 3, 0) + COUNTA(D6:S6)) > 3, "확인요망", "")
A7: 반지 | F7: 2.1 | H7: 2.1 | P7: 0.7 | T7: =IF((IF(B7, 3, 0) + IF(C7, 3, 0) + COUNTA(D7:S7)) > 3, "확인요망", "")
A8: 엠블럼 | F8: 2.1 | H8: 2.1 | P8: 0.7 | T8: =IF((IF(B8, 3, 0) + IF(C8, 3, 0) + COUNTA(D8:S8)) > 3, "확인요망", "")
A9: 모자 | F9: 2.1 | H9: 2.1 | P9: 0.7 | T9: =IF((IF(B9, 3, 0) + IF(C9, 3, 0) + COUNTA(D9:S9)) > 3, "확인요망", "")
F10: 2.1 | H10: 2.1 | P10: 0.7 | T10: =IF((IF(B10, 3, 0) + IF(C10, 3, 0) + COUNTA(D10:S10)) > 3, "확인요망", "")
F11: 2.1 | H11: 2.1 | P11: 0.7 | T11: =IF((IF(B11, 3, 0) + IF(C11, 3, 0) + COUNTA(D11:S11)) > 3, "확인요망", "")
A12: 상의 | F12: 2.2 | H12: 2.2 | O12: 0.75 | T12: =IF((IF(B12, 3, 0) + IF(C12, 3, 0) + COUNTA(D12:S12)) > 3, "확인요망", "")
F13: 2.2 | H13: 2.2 | I13: 2.2 | T13: =IF((IF(B13, 3, 0) + IF(C13, 3, 0) + COUNTA(D13:S13)) > 3, "확인요망", "")
F14: 2.2 | H14: 2.2 | J14: 2.2 | T14: =IF((IF(B14, 3, 0) + IF(C14, 3, 0) + COUNTA(D14:S14)) > 3, "확인요망", "")
A15: 하의 | F15: 2.1 | H15: 2.1 | I15: 2.1 | T15: =IF((IF(B15, 3, 0) + IF(C15, 3, 0) + COUNTA(D15:S15)) > 3, "확인요망", "")
F16: 2.2 | H16: 2.2 | I16: 2.2 | T16: =IF((IF(B16, 3, 0) + IF(C16, 3, 0) + COUNTA(D16:S16)) > 3, "확인요망", "")
F17: 2.2 | H17: 2.2 | K17: 2.2 | T17: =IF((IF(B17, 3, 0) + IF(C17, 3, 0) + COUNTA(D17:S17)) > 3, "확인요망", "")
A18: 장갑 | F18: 2.2 | H18: 2.2 | S18: 0.75 | T18: =IF((IF(B18, 3, 0) + IF(C18, 3, 0) + COUNTA(D18:S18)) > 3, "확인요망", "")
F19: 2.2 | H19: 2.2 | R19: 0.75 | T19: =IF((IF(B19, 3, 0) + IF(C19, 3, 0) + COUNTA(D19:S19)) > 3, "확인요망", "")
E20: 2.1 | F20: 2.1 | H20: 2.1 | T20: =IF((IF(B20, 3, 0) + IF(C20, 3, 0) + COUNTA(D20:S20)) > 3, "확인요망", "")
A21: 신발 | F21: 2.1 | H21: 2.1 | R21: 0.7 | T21: =IF((IF(B21, 3, 0) + IF(C21, 3, 0) + COUNTA(D21:S21)) > 3, "확인요망", "")
F22: 2.1 | H22: 2.1 | R22: 0.7 | T22: =IF((IF(B22, 3, 0) + IF(C22, 3, 0) + COUNTA(D22:S22)) > 3, "확인요망", "")
F23: 2.1 | G23: 2.1 | H23: 2.1 | T23: =IF((IF(B23, 3, 0) + IF(C23, 3, 0) + COUNTA(D23:S23)) > 3, "확인요망", "")
A25: 합계 | B25: =MAX(B2:B23)/100 -> 0 | C25: =MAX(C2:C23)/100 -> 0 | D25: =SUM(D2:D23)/100+$C$25 -> 0 | E25: =SUM(E2:E23)/100+$C$25 -> 0.021 | F25: =SUM(F2:F23)/100+$C$25 -> 0.471 | G25: =SUM(G2:G23)/100+$C$25 -> 0.021 | H25: =SUM(H2:H23)/100+$C$25 -> 0.471 | I25: =SUM(I2:I23)/100+$C$25 -> 0.065 | J25: =SUM(J2:J23)/100+$C$25 -> 0.022 | K25: =SUM(K2:K23)/100+$C$25 -> 0.022 | L25: =SUM(L2:L23)/100 -> 0 | M25: =SUM(M2:M23)/100 -> 0 | N25: =SUM(N2:N23)/100 -> 0.0285 | O25: =SUM(O2:O23)/100 -> 0.0075 | P25: =SUM(P2:P23)/100 -> 0.0425 | Q25: =SUM(Q2:Q23)/100 -> 0 | R25: =SUM(R2:R23)/100 -> 0.0215 | S25: =SUM(S2:S23)/100 -> 0.0075 | T25: =IF(COUNTIF(T2:T23, "확인요망")>0, "확인요망", "")
M27: 예상 DPS | P27: ='종합'!K44 -> 3463303.9

Sheet 무기룬
A1: 무기 룬 | B1: 사용여부 | C1: 가동률 | D1: 공증 | E1: 조건공증 | F1: 주피증 | G1: 받피증 | H1: 강타 | I1: 연타 | J1: 추피 | K1: 치피 | L1: 콤보피증 | M1: 멀티피증 | N1: 스킬피증 | O1: 추확 | P1: 치확 | Q1: 캐속 | R1: 무방 | S1: 재속 | T1: 스속 | U1: 공속 | V1: 공추 | W1: 궁획 | X1: 피해 | Y1: 지속피해 | Z1: 이속 | AA1: 특이사항 | AC1: 연타가동률
A2: 천 자루 검 | B2: =IF(COUNTIF('종합'!$B$11:$G$15, A2) > 0, TRUE, "") | C2: 1 | D2: 0.24
A3: 불길 | B3: =IF(COUNTIF('종합'!$B$11:$G$15, A3) > 0, TRUE, "") | C3: 1 | P3: {=0.18+IF(SUMPRODUCT(('종합'!$B$11:$G$15=INDIRECT("A"&ROW())) * ('종합'!$C$11:$H$15="초월+")), 0.02, 0)+IF(SUMPRODUCT(('종합'!$B$11:$G$15=INDIRECT("A"&ROW())) * ('종합'!$C$11:$H$15="초월++")), 0.04, 0)} -> 0.18 | Y3: =3.6/(10/C3) -> 0.36 | AC3: 0.4
A4: 결정 | B4: =IF(COUNTIF('종합'!$B$11:$G$15, A4) > 0, TRUE, "") | C4: 1 | O4: {=0.18+IF(SUMPRODUCT(('종합'!$B$11:$G$15=INDIRECT("A"&ROW())) * ('종합'!$C$11:$H$15="초월+")), 0.02, 0)+IF(SUMPRODUCT(('종합'!$B$11:$G$15=INDIRECT("A"&ROW())) * ('종합'!$C$11:$H$15="초월++")), 0.04, 0)} -> 0.18 | Y4: =3.6/(10/C4) -> 0.36 | AC4: 0.4
A5: 뇌명 | B5: =IF(COUNTIF('종합'!$B$11:$G$15, A5) > 0, TRUE, "") | C5: 1 | H5: {=0.2+IF(SUMPRODUCT(('종합'!$B$11:$G$15=INDIRECT("A"&ROW())) * ('종합'!$C$11:$H$15="초월+")), 0.02, 0)+IF(SUMPRODUCT(('종합'!$B$11:$G$15=INDIRECT("A"&ROW())) * ('종합'!$C$11:$H$15="초월++")), 0.04, 0)} -> 0.2 | Y5: =3.6/(10/C5) -> 0.36 | AC5: 0.4
A6: 독사+ | B6: =IF(COUNTIF('종합'!$B$11:$G$15, A6) > 0, TRUE, "") | C6: 1 | I6: {=0.2+IF(SUMPRODUCT(('종합'!$B$11:$G$15=INDIRECT("A"&ROW())) * ('종합'!$C$11:$H$15="초월+")), 0.02, 0)+IF(SUMPRODUCT(('종합'!$B$11:$G$15=INDIRECT("A"&ROW())) * ('종합'!$C$11:$H$15="초월++")), 0.04, 0)} -> 0.2 | Y6: =3.6/(10/C6) -> 0.36 | AC6: 0.4
A7: 공포 | B7: =IF(COUNTIF('종합'!$B$11:$G$15, A7) > 0, TRUE, "") | C7: 1 | K7: {=0.18+IF(SUMPRODUCT(('종합'!$B$11:$G$15=INDIRECT("A"&ROW())) * ('종합'!$C$11:$H$15="초월+")), 0.02, 0)+IF(SUMPRODUCT(('종합'!$B$11:$G$15=INDIRECT("A"&ROW())) * ('종합'!$C$11:$H$15="초월++")), 0.04, 0)} -> 0.18 | Y7: =3.6/(10/C7) -> 0.36 | AC7: 0.4
A8: 집행자 | B8: =IF(COUNTIF('종합'!$B$11:$G$15, A8) > 0, TRUE, "") | C8: 1 | F8: {=0.1+IF(SUMPRODUCT(('종합'!$B$11:$G$15=INDIRECT("A"&ROW())) * ('종합'!$C$11:$H$15="초월+")), 0.02, 0)+IF(SUMPRODUCT(('종합'!$B$11:$G$15=INDIRECT("A"&ROW())) * ('종합'!$C$11:$H$15="초월++")), 0.04, 0)} -> 0.1 | Y8: =3.6/(10/C8) -> 0.36 | AC8: 0.4
A9: 야수+ | B9: =IF(COUNTIF('종합'!$B$11:$G$15, A9) > 0, TRUE, "") | C9: 1 | F9: {=0.2+IF(SUMPRODUCT(('종합'!$B$11:$G$15=INDIRECT("A"&ROW())) * ('종합'!$C$11:$H$15="초월+")), 0.02, 0)+IF(SUMPRODUCT(('종합'!$B$11:$G$15=INDIRECT("A"&ROW())) * ('종합'!$C$11:$H$15="초월++")), 0.04, 0)} -> 0.2 | Y9: =3.6/(10/C9) -> 0.36 | AC9: 0.4
A10: 밤+ | B10: =IF(COUNTIF('종합'!$B$11:$G$15, A10) > 0, TRUE, "") | C10: 1 | D10: {=0.2+IF(SUMPRODUCT(('종합'!$B$11:$G$15=INDIRECT("A"&ROW())) * ('종합'!$C$11:$H$15="초월+")), 0.02, 0)+IF(SUMPRODUCT(('종합'!$B$11:$G$15=INDIRECT("A"&ROW())) * ('종합'!$C$11:$H$15="초월++")), 0.04, 0)} -> 0.2 | Y10: =3.6/(10/C10) -> 0.36 | AC10: 0.4
A11: 투사+ | B11: =IF(COUNTIF('종합'!$B$11:$G$15, A11) > 0, TRUE, "") | C11: 1 | F11: {=0.33+IF(SUMPRODUCT(('종합'!$B$11:$G$15=INDIRECT("A"&ROW())) * ('종합'!$C$11:$H$15="초월+")), 0.02, 0)+IF(SUMPRODUCT(('종합'!$B$11:$G$15=INDIRECT("A"&ROW())) * ('종합'!$C$11:$H$15="초월++")), 0.04, 0)} -> 0.33 | M11: {=IF('방어구룬'!B68, 0, -0.1+IF(SUMPRODUCT(('종합'!$B$11:$G$15=INDIRECT("A"&ROW())) * ('종합'!$C$11:$H$15="초월+")), 0.02, 0)+IF(SUMPRODUCT(('종합'!$B$11:$G$15=INDIRECT("A"&ROW())) * ('종합'!$C$11:$H$15="초월++")), 0.04, 0))} -> -0.1 | AA11: 결함
A12: 은둔자+ | B12: =IF(COUNTIF('종합'!$B$11:$G$15, A12) > 0, TRUE, "") | C12: 1 | D12: {=0.33+IF(SUMPRODUCT(('종합'!$B$11:$G$15=INDIRECT("A"&ROW())) * ('종합'!$C$11:$H$15="초월+")), 0.015, 0)+IF(SUMPRODUCT(('종합'!$B$11:$G$15=INDIRECT("A"&ROW())) * ('종합'!$C$11:$H$15="초월++")), 0.03, 0)} -> 0.33 | S12: {=IF('방어구룬'!B68, 0, -0.09+IF(SUMPRODUCT(('종합'!$B$11:$G$15=INDIRECT("A"&ROW())) * ('종합'!$C$11:$H$15="초월+")), 0.02, 0)+IF(SUMPRODUCT(('종합'!$B$11:$G$15=INDIRECT("A"&ROW())) * ('종합'!$C$11:$H$15="초월++")), 0.04, 0))} -> -0.09 | AA12: 결함
A13: 망각+ | B13: =IF(COUNTIF('종합'!$B$11:$G$15, A13) > 0, TRUE, "") -> TRUE | C13: 1 | D13: {=0.19+IF(SUMPRODUCT(('종합'!$B$11:$G$15=INDIRECT("A"&ROW())) * ('종합'!$C$11:$H$15="초월+")), 0.02, 0)+IF(SUMPRODUCT(('종합'!$B$11:$G$15=INDIRECT("A"&ROW())) * ('종합'!$C$11:$H$15="초월++")), 0.04, 0)} -> 0.23 | AA13: 평타쿨감9%
A14: 망각(에픽) | B14: =IF(COUNTIF('종합'!$B$11:$G$15, A14) > 0, TRUE, "") | C14: 1 | D14: 0.11 | AA14: 평타쿨감8%
A15: 서리바람+ | B15: =IF(COUNTIF('종합'!$B$11:$G$15, A15) > 0, TRUE, "") | C15: 1 | D15: {=0.2+IF(SUMPRODUCT(('종합'!$B$11:$G$15=INDIRECT("A"&ROW())) * ('종합'!$C$11:$H$15="초월+")), 0.02, 0)+IF(SUMPRODUCT(('종합'!$B$11:$G$15=INDIRECT("A"&ROW())) * ('종합'!$C$11:$H$15="초월++")), 0.04, 0)} -> 0.2 | Q15: 0.25
A16: 옛 마법사 | B16: =IF(COUNTIF('종합'!$B$11:$G$15, A16) > 0, TRUE, "") | C16: 1 | F16: {=IF('방어구룬'!B68, 0, -0.1+IF(SUMPRODUCT(('종합'!$B$11:$G$15=INDIRECT("A"&ROW())) * ('종합'!$C$11:$H$15="초월+")), 0.02, 0)+IF(SUMPRODUCT(('종합'!$B$11:$G$15=INDIRECT("A"&ROW())) * ('종합'!$C$11:$H$15="초월++")), 0.04, 0))} -> -0.1 | S16: {=0.29+IF(SUMPRODUCT(('종합'!$B$11:$G$15=INDIRECT("A"&ROW())) * ('종합'!$C$11:$H$15="초월+")), 0.02, 0)+IF(SUMPRODUCT(('종합'!$B$11:$G$15=INDIRECT("A"&ROW())) * ('종합'!$C$11:$H$15="초월++")), 0.04, 0)} -> 0.29
A17: 물결치는 날 | B17: =IF(COUNTIF('종합'!$B$11:$G$15, A17) > 0, TRUE, "") | C17: 1 | U17: 0.1 | AA17: 평타1.52피해 | AB17: {=1.52+IF(SUMPRODUCT(('종합'!$B$11:$G$15=INDIRECT("A"&ROW())) * ('종합'!$C$11:$H$15="초월+")), 0.11, 0)+IF(SUMPRODUCT(('종합'!$B$11:$G$15=INDIRECT("A"&ROW())) * ('종합'!$C$11:$H$15="초월++")), 0.21, 0)} -> 1.52
A18: 파괴자+ | B18: =IF(COUNTIF('종합'!$B$11:$G$15, A18) > 0, TRUE, "") | C18: 1 | D18: {=0.18+IF(SUMPRODUCT(('종합'!$B$11:$G$15=INDIRECT("A"&ROW())) * ('종합'!$C$11:$H$15="초월+")), 0.02, 0)+IF(SUMPRODUCT(('종합'!$B$11:$G$15=INDIRECT("A"&ROW())) * ('종합'!$C$11:$H$15="초월++")), 0.04, 0)} -> 0.18 | R18: 0.48
A19: 검무+ | B19: =IF(COUNTIF('종합'!$B$11:$G$15, A19) > 0, TRUE, "") | C19: =IF('종합'!C3<=0, 0, LET( R, ('종합'!K39 + '종합'!K40), T, '종합'!C3, D, 10, M, 10, IF(R<=0, 0, LET( SPS, IF('방어구룬'!B49=TRUE, R * 2, R), SSS, MIN(SPS * D, M), T_ramp, SSS / SPS, IF(T <= T_ramp, 0.5 * SPS * T, (SSS * (T - 0.5 * T_ramp)) / T ) )) ))/10 -> 0.88792361 | E19: {=(0.2+IF(SUMPRODUCT(('종합'!$B$11:$G$15=INDIRECT("A"&ROW())) * ('종합'!$C$11:$H$15="초월+")), 0.02, 0)+IF(SUMPRODUCT(('종합'!$B$11:$G$15=INDIRECT("A"&ROW())) * ('종합'!$C$11:$H$15="초월++")), 0.04, 0))*C19} -> 0.17758472 | P19: =0.1*C19 -> 0.088792361 | AA19: 누적
A20: 무수한 궤적 | B20: =IF(COUNTIF('종합'!$B$11:$G$15, A20) > 0, TRUE, "") | C20: 1 | D20: {=0.17+IF(SUMPRODUCT(('종합'!$B$11:$G$15=INDIRECT("A"&ROW())) * ('종합'!$C$11:$H$15="초월+")), 0.02, 0)+IF(SUMPRODUCT(('종합'!$B$11:$G$15=INDIRECT("A"&ROW())) * ('종합'!$C$11:$H$15="초월++")), 0.04, 0)} -> 0.17 | U20: 0.3 | V20: 0.3
A21: 마지막 자비 | B21: =IF(COUNTIF('종합'!$B$11:$G$15, A21) > 0, TRUE, "") | C21: 0.6 | D21: {=0.2+IF(SUMPRODUCT(('종합'!$B$11:$G$15=INDIRECT("A"&ROW())) * ('종합'!$C$11:$H$15="초월+")), 0.02, 0)+IF(SUMPRODUCT(('종합'!$B$11:$G$15=INDIRECT("A"&ROW())) * ('종합'!$C$11:$H$15="초월++")), 0.04, 0)} -> 0.2 | E21: =0.2*C21 -> 0.12
A22: 끝없는 순환 | B22: =IF(COUNTIF('종합'!$B$11:$G$15, A22) > 0, TRUE, "") | C22: 1
A23: 종언+ | B23: =IF(COUNTIF('종합'!$B$11:$G$15, A23) > 0, TRUE, "") | C23: 0.1 | D23: {=0.24+IF(SUMPRODUCT(('종합'!$B$11:$G$15=INDIRECT("A"&ROW())) * ('종합'!$C$11:$H$15="초월+")), 0.02, 0)+IF(SUMPRODUCT(('종합'!$B$11:$G$15=INDIRECT("A"&ROW())) * ('종합'!$C$11:$H$15="초월++")), 0.04, 0)} -> 0.24 | E23: =0.2*C23 -> 0.02 | AA23: 쫄한정
A24: 영웅 | B24: =IF(COUNTIF('종합'!$B$11:$G$15, A24) > 0, TRUE, "") | C24: 1 | D24: {=0.043+IF(SUMPRODUCT(('종합'!$B$11:$G$15=INDIRECT("A"&ROW())) * ('종합'!$C$11:$H$15="초월+")), 0.02, 0)+IF(SUMPRODUCT(('종합'!$B$11:$G$15=INDIRECT("A"&ROW())) * ('종합'!$C$11:$H$15="초월++")), 0.04, 0)} -> 0.043 | H24: 0.043 | I24: 0.043 | K24: 0.043 | L24: 0.043 | M24: 0.043 | N24: 0.043
A25: 만 갈래 물길 | B25: =IF(COUNTIF('종합'!$B$11:$G$15, A25) > 0, TRUE, "") | C25: 1 | D25: 0.35 | AA25: 무기룬에서 수치입력
A26: 흰 까마귀 | B26: =IF(COUNTIF('종합'!$B$11:$G$15, A26) > 0, TRUE, "") | C26: 15 | E26: =if(C26>14,0.07,0) -> 0.07 | F26: =if(C26>9,0.07,0) -> 0.07 | Q26: 0.1 | S26: 0.1 | T26: 0.1 | U26: 0.1 | Z26: 0.1 | AA26: 무기룬에서 강화입력
A27: 메아리치는 진노 | B27: =IF(COUNTIF('종합'!$B$11:$G$15, A27) > 0, TRUE, "") | C27: 15 | D27: 0.05 | E27: =if(C27>9,0.03,0)+if(C27>14,0.03,0) -> 0.06 | X27: =1.1/4 -> 0.275 | Y27: =0.35/4 -> 0.0875 | AA27: 광역속성피해
A28: 무한 | B28: =IF(COUNTIF('종합'!$B$11:$G$15, A28) > 0, TRUE, "") | C28: 1 | D28: 0.2 | U28: 0.12 | AA28: 평타쿨감9%
A29: 빈값 | B29: =IF(COUNTIF('종합'!$B$11:$G$15, A29) > 0, TRUE, "")
A30: 폭군 | B30: =IF(COUNTIF('종합'!$B$11:$G$15, A30) > 0, TRUE, "") | K30: {=LET( 전투시간, '종합'!C3, 치확, '종합'!K17, 공속, ('종합'!K39 + '종합'!K40) * 1.5, 룬효과, '방어구룬'!B68, 순변화량, 1 - (공속 * 치확), 평균중첩, IF(OR(룬효과, 순변화량 >= 0), 10, LET( 소모시간, -10 / 순변화량, IF(전투시간 <= 소모시간, (10 + (10 + 순변화량 * 전투시간)) / 2, (5 * 소모시간) / 전투시간 ) ) ), 평균중첩 * (0.035 + IF(SUMPRODUCT(('종합'!$B$11:$G$15=INDIRECT("A"&ROW())) * ('종합'!$C$11:$H$15="초월+")), 0.003, 0) + IF(SUMPRODUCT(('종합'!$B$11:$G$15=INDIRECT("A"&ROW())) * ('종합'!$C$11:$H$15="초월++")), 0.005, 0) ) )} -> 0.35
A31: 천체 정렬 | B31: =IF(COUNTIF('종합'!$B$11:$G$15, A31) > 0, TRUE, "") | E31: {=LET( 전투시간, '종합'!C3, 룬적용, '방어구룬'!B49, 시작중첩, IF(룬적용, 4, 2), 증가량, IF(룬적용, 2, 1), 상승1, (6 - 시작중첩) / 증가량 * 10, 주기1, 상승1 + 20, 상승2, 60 / 증가량, 주기2, 상승2 + 20, 면적1상승, 10 * ((상승1 / 10) * 시작중첩 + 증가량 * (상승1 / 10) * (상승1 / 10 - 1) / 2), 면적1전체, 면적1상승 + 120, 면적2상승, 10 * (증가량 * (상승2 / 10) * (상승2 / 10 - 1) / 2), 면적2전체, 면적2상승 + 120, 누적면적, IF(전투시간 <= 주기1, IF(전투시간 <= 상승1, LET(n, QUOTIENT(전투시간, 10), (10 * (n * 시작중첩 + 증가량 * n * (n - 1) / 2)) + (시작중첩 + n * 증가량) * MOD(전투시간, 10)), 면적1상승 + 6 * (전투시간 - 상승1) ), 면적1전체 + QUOTIENT(전투시간 - 주기1, 주기2) * 면적2전체 + LET(남은시간, MOD(전투시간 - 주기1, 주기2), IF(남은시간 <= 상승2, LET(m, QUOTIENT(남은시간, 10), (10 * (증가량 * m * (m - 1) / 2)) + (m * 증가량) * MOD(남은시간, 10)), 면적2상승 + 6 * (남은시간 - 상승2) ) ) ), 보너스, IF(SUMPRODUCT(('종합'!$B$11:$G$15=INDIRECT("A"&ROW())) * ('종합'!$C$11:$H$15="초월+")), 0.002, 0) + IF(SUMPRODUCT(('종합'!$B$11:$G$15=INDIRECT("A"&ROW())) * ('종합'!$C$11:$H$15="초월++")), 0.004, 0), IFERROR(누적면적 / 전투시간, 시작중첩) * (0.03 + 보너스) )} -> 0.1025 | F31: {=LET( 전투시간, '종합'!C3, 룬적용, '방어구룬'!B49, 시작중첩, IF(룬적용, 4, 2), 증가량, IF(룬적용, 2, 1), 상승1, (6 - 시작중첩) / 증가량 * 10, 주기1, 상승1 + 20, 상승2, 60 / 증가량, 주기2, 상승2 + 20, 면적1상승, 10 * ((상승1 / 10) * 시작중첩 + 증가량 * (상승1 / 10) * (상승1 / 10 - 1) / 2), 면적1전체, 면적1상승 + 120, 면적2상승, 10 * (증가량 * (상승2 / 10) * (상승2 / 10 - 1) / 2), 면적2전체, 면적2상승 + 120, 누적면적, IF(전투시간 <= 주기1, IF(전투시간 <= 상승1, LET(n, QUOTIENT(전투시간, 10), (10 * (n * 시작중첩 + 증가량 * n * (n - 1) / 2)) + (시작중첩 + n * 증가량) * MOD(전투시간, 10)), 면적1상승 + 6 * (전투시간 - 상승1) ), 면적1전체 + QUOTIENT(전투시간 - 주기1, 주기2) * 면적2전체 + LET(남은시간, MOD(전투시간 - 주기1, 주기2), IF(남은시간 <= 상승2, LET(m, QUOTIENT(남은시간, 10), (10 * (증가량 * m * (m - 1) / 2)) + (m * 증가량) * MOD(남은시간, 10)), 면적2상승 + 6 * (남은시간 - 상승2) ) ) ), 보너스, IF(SUMPRODUCT(('종합'!$B$11:$G$15=INDIRECT("A"&ROW())) * ('종합'!$C$11:$H$15="초월+")), 0.002, 0) + IF(SUMPRODUCT(('종합'!$B$11:$G$15=INDIRECT("A"&ROW())) * ('종합'!$C$11:$H$15="초월++")), 0.004, 0), IFERROR(누적면적 / 전투시간, 시작중첩) * (0.03 + 보너스) )} -> 0.1025 | AA31: =LET( 전투시간, '종합'!C3, 룬적용, '방어구룬'!B49, 상승시간1, IF(룬적용, 10, 40), 주기1, 상승시간1 + 20, 상승시간2, IF(룬적용, 30, 60), 주기2, 상승시간2 + 20, IF(전투시간 < 상승시간1, 0, 1 + INT(MAX(0, 전투시간 - 주기1) / 주기2) ) ) -> 1 | AB31: =LET( 전투시간, '종합'!C3, 룬적용, '방어구룬'!B49, 최대횟수, '무기룬'!AA31, 상승1, IF(룬적용, 10, 40), 주기1, 상승1 + 20, 상승2, IF(룬적용, 30, 60), 주기2, 상승2 + 20, 마지막_활성시점, IF(최대횟수 <= 1, 상승1, 주기1 + (최대횟수 - 2) * 주기2 + 상승2), 마지막_유지분, IF(최대횟수 < 1, 0, MAX(0, MIN(20, 전투시간 - 마지막_활성시점))), 총_활성시간, IF(최대횟수 < 1, 0, (MAX(0, 최대횟수 - 1) * 20) + 마지막_유지분), IFERROR((총_활성시간 / 전투시간) * 0.2, 0) ) -> 0.033333333
AF38: 3982 | AH38: 4380 | AI38: 1393
AH39: =AH38/AF38 -> 1.0999498 | AI39: =AI38/AF38 -> 0.34982421
AH42: =AH39+AI39 -> 1.449774
AB65: 0.3 | AC65: 0.3
AB70: 0.02 | AC70: 0.02

Sheet 방어구룬
A1: 방어구 룬 | B1: 사용여부 | C1: 가동률 | D1: 공증 | E1: 조건공증 | F1: 주피증 | G1: 받피증 | H1: 강타 | I1: 연타 | J1: 추피 | K1: 치피 | L1: 콤보피증 | M1: 멀티피증 | N1: 스킬피증 | O1: 추확 | P1: 치확 | Q1: 캐속 | R1: 무방 | S1: 재속 | T1: 스속 | U1: 공속 | V1: 공추 | W1: 궁획 | X1: 피해 | Y1: 지속피해 | Z1: 이속 | AA1: 특이사항 | AC1: 연타가동률
A2: 횃불 | B2: =IF(COUNTIF('종합'!$B$11:$G$15, A2) > 0, TRUE, "") | C2: 1 | P2: 0.1
A3: 쇄빙 | B3: =IF(COUNTIF('종합'!$B$11:$G$15, A3) > 0, TRUE, "") | C3: 1 | O3: 0.1
A4: 마나 격류 | B4: =IF(COUNTIF('종합'!$B$11:$G$15, A4) > 0, TRUE, "") | C4: 1 | E4: 0.14
A5: 바위거인 | B5: =IF(COUNTIF('종합'!$B$11:$G$15, A5) > 0, TRUE, "") | C5: 0.7 | E5: =0.2*C5 -> 0.14
A6: 평원 방랑자 | B6: =IF(COUNTIF('종합'!$B$11:$G$15, A6) > 0, TRUE, "") | C6: 1 | F6: 0.12 | Z6: 0.3
A7: 파멸의 낙인 | B7: =IF(COUNTIF('종합'!$B$11:$G$15, A7) > 0, TRUE, "") | C7: 1 | X7: =if(B8, 0.162,0.144) -> 0.144
A8: 공명하는 수정 | B8: =IF(COUNTIF('종합'!$B$11:$G$15, A8) > 0, TRUE, "") | C8: 1 | F8: =if(B7, 0.168,0.1292) -> 0.1292
A9: 여명+ | B9: =IF(COUNTIF('종합'!$B$11:$G$15, A9) > 0, TRUE, "") | C9: =min(('종합'!K39)*if('방어구룬'!B49=true,10/6,10/3),1) -> 1 | E9: {=(0.21+IF(SUMPRODUCT(('종합'!$B$11:$G$15=INDIRECT("A"&ROW())) * ('종합'!$C$11:$H$15="초월+")), 0.018, 0)+IF(SUMPRODUCT(('종합'!$B$11:$G$15=INDIRECT("A"&ROW())) * ('종합'!$C$11:$H$15="초월++")), 0.03, 0))*C9} -> 0.21
A10: 황혼 | B10: =IF(COUNTIF('종합'!$B$11:$G$15, A10) > 0, TRUE, "") | C10: =IF('방어구룬'!B49=TRUE, MIN(('종합'!K39+'종합'!I40)*16, 16), MIN(('종합'!K39+'종합'!I40)*8, 16)) -> 4.8455762 | F10: {=(0.014+IF(SUMPRODUCT(('종합'!$B$11:$G$15=INDIRECT("A"&ROW())) * ('종합'!$C$11:$H$15="초월+")), 0.002, 0)+IF(SUMPRODUCT(('종합'!$B$11:$G$15=INDIRECT("A"&ROW())) * ('종합'!$C$11:$H$15="초월++")), 0.003, 0))*C10} -> 0.067838067
A11: 바위 감시자 | B11: =IF(COUNTIF('종합'!$B$11:$G$15, A11) > 0, TRUE, "") | C11: =MIN(6*IF('방어구룬'!B55=TRUE, ('종합'!K39+'종합'!K40)*2, ('종합'!K39+'종합'!K40))/7, 1) -> 0.7941677 | E11: {=C11*(0.22+IF(SUMPRODUCT(('종합'!$B$11:$G$15=INDIRECT("A"&ROW())) * ('종합'!$C$11:$H$15="초월+")), 0.02, 0)+IF(SUMPRODUCT(('종합'!$B$11:$G$15=INDIRECT("A"&ROW())) * ('종합'!$C$11:$H$15="초월++")), 0.04, 0))} -> 0.17471689
A12: 쇄도+ | B12: =IF(COUNTIF('종합'!$B$11:$G$15, A12) > 0, TRUE, "") | C12: 1 | Q12: {=0.2+IF(SUMPRODUCT(('종합'!$B$11:$G$15=INDIRECT("A"&ROW())) * ('종합'!$C$11:$H$15="초월+")), 0.02, 0)+IF(SUMPRODUCT(('종합'!$B$11:$G$15=INDIRECT("A"&ROW())) * ('종합'!$C$11:$H$15="초월++")), 0.04, 0)} -> 0.2 | T12: {=0.2+IF(SUMPRODUCT(('종합'!$B$11:$G$15=INDIRECT("A"&ROW())) * ('종합'!$C$11:$H$15="초월+")), 0.02, 0)+IF(SUMPRODUCT(('종합'!$B$11:$G$15=INDIRECT("A"&ROW())) * ('종합'!$C$11:$H$15="초월++")), 0.04, 0)} -> 0.2
A13: 무도가+ | B13: =IF(COUNTIF('종합'!$B$11:$G$15, A13) > 0, TRUE, "") | C13: 1 | D13: {=0.15+IF(SUMPRODUCT(('종합'!$B$11:$G$15=INDIRECT("A"&ROW())) * ('종합'!$C$11:$H$15="초월+")), 0.03, 0)+IF(SUMPRODUCT(('종합'!$B$11:$G$15=INDIRECT("A"&ROW())) * ('종합'!$C$11:$H$15="초월++")), 0.05, 0)} -> 0.15 | W13: 0.2
A14: 해결사+ | B14: =IF(COUNTIF('종합'!$B$11:$G$15, A14) > 0, TRUE, "") | C14: 1 | U14: {=0.3+IF(SUMPRODUCT(('종합'!$B$11:$G$15=INDIRECT("A"&ROW())) * ('종합'!$C$11:$H$15="초월+")), 0.03, 0)+IF(SUMPRODUCT(('종합'!$B$11:$G$15=INDIRECT("A"&ROW())) * ('종합'!$C$11:$H$15="초월++")), 0.06, 0)} -> 0.3 | V14: {=0.3+IF(SUMPRODUCT(('종합'!$B$11:$G$15=INDIRECT("A"&ROW())) * ('종합'!$C$11:$H$15="초월+")), 0.03, 0)+IF(SUMPRODUCT(('종합'!$B$11:$G$15=INDIRECT("A"&ROW())) * ('종합'!$C$11:$H$15="초월++")), 0.06, 0)} -> 0.3
A15: 들불 | B15: =IF(COUNTIF('종합'!$B$11:$G$15, A15) > 0, TRUE, "") | C15: 1 | P15: {=(0.14+IF(SUMPRODUCT(('종합'!$B$11:$G$15=INDIRECT("A"&ROW())) * ('종합'!$C$11:$H$15="초월+")), 0.02, 0)+IF(SUMPRODUCT(('종합'!$B$11:$G$15=INDIRECT("A"&ROW())) * ('종합'!$C$11:$H$15="초월++")), 0.04, 0))*C15} -> 0.14
A16: 설산 | B16: =IF(COUNTIF('종합'!$B$11:$G$15, A16) > 0, TRUE, "") | C16: 1 | O16: {=(0.16+IF(SUMPRODUCT(('종합'!$B$11:$G$15=INDIRECT("A"&ROW())) * ('종합'!$C$11:$H$15="초월+")), 0.02, 0)+IF(SUMPRODUCT(('종합'!$B$11:$G$15=INDIRECT("A"&ROW())) * ('종합'!$C$11:$H$15="초월++")), 0.04, 0))*C16} -> 0.16
A17: 절개+ | B17: =IF(COUNTIF('종합'!$B$11:$G$15, A17) > 0, TRUE, "") | C17: 1 | E17: {=(0.2+IF(SUMPRODUCT(('종합'!$B$11:$G$15=INDIRECT("A"&ROW())) * ('종합'!$C$11:$H$15="초월+")), 0.02, 0)+IF(SUMPRODUCT(('종합'!$B$11:$G$15=INDIRECT("A"&ROW())) * ('종합'!$C$11:$H$15="초월++")), 0.04, 0))*C17} -> 0.2
A18: 환영+ | B18: =IF(COUNTIF('종합'!$B$11:$G$15, A18) > 0, TRUE, "") | C18: 1 | D18: {=0.18+IF(SUMPRODUCT(('종합'!$B$11:$G$15=INDIRECT("A"&ROW())) * ('종합'!$C$11:$H$15="초월+")), 0.02, 0)+IF(SUMPRODUCT(('종합'!$B$11:$G$15=INDIRECT("A"&ROW())) * ('종합'!$C$11:$H$15="초월++")), 0.04, 0)} -> 0.18 | G18: =0.1*C18 -> 0.1 | AA18: 방어구파괴
A19: 황금 들판 | B19: =IF(COUNTIF('종합'!$B$11:$G$15, A19) > 0, TRUE, "") | C19: 1 | D19: {=0.2+IF(SUMPRODUCT(('종합'!$B$11:$G$15=INDIRECT("A"&ROW())) * ('종합'!$C$11:$H$15="초월+")), 0.02, 0)+IF(SUMPRODUCT(('종합'!$B$11:$G$15=INDIRECT("A"&ROW())) * ('종합'!$C$11:$H$15="초월++")), 0.04, 0)} -> 0.2 | E19: =0.2*C19-0.2 -> 0
A20: 모래 폭풍 | B20: =IF(COUNTIF('종합'!$B$11:$G$15, A20) > 0, TRUE, "") | C20: 1 | T20: {=0.1+IF(SUMPRODUCT(('종합'!$B$11:$G$15=INDIRECT("A"&ROW())) * ('종합'!$C$11:$H$15="초월+")), 0.02, 0)+IF(SUMPRODUCT(('종합'!$B$11:$G$15=INDIRECT("A"&ROW())) * ('종합'!$C$11:$H$15="초월++")), 0.04, 0)} -> 0.1 | U20: {=0.1+IF(SUMPRODUCT(('종합'!$B$11:$G$15=INDIRECT("A"&ROW())) * ('종합'!$C$11:$H$15="초월+")), 0.02, 0)+IF(SUMPRODUCT(('종합'!$B$11:$G$15=INDIRECT("A"&ROW())) * ('종합'!$C$11:$H$15="초월++")), 0.04, 0)} -> 0.1 | AA20: 무방비조건
A21: 황폐+ | B21: =IF(COUNTIF('종합'!$B$11:$G$15, A21) > 0, TRUE, "") | C21: 0 | F21: =0.12*C21 -> 0 | O21: =0.07*C21 -> 0
A22: 신성한 칙령 | B22: =IF(COUNTIF('종합'!$B$11:$G$15, A22) > 0, TRUE, "") | C22: 0 | E22: {=(0.15+IF(SUMPRODUCT(('종합'!$B$11:$G$15=INDIRECT("A"&ROW())) * ('종합'!$C$11:$H$15="초월+")), 0.03, 0))*C22} -> 0
A23: 준비된 자 | B23: =IF(COUNTIF('종합'!$B$11:$G$15, A23) > 0, TRUE, "") | C23: 0.5 | E23: {=(0.2+IF(SUMPRODUCT(('종합'!$B$11:$G$15=INDIRECT("A"&ROW())) * ('종합'!$C$11:$H$15="초월+")), 0.02, 0)+IF(SUMPRODUCT(('종합'!$B$11:$G$15=INDIRECT("A"&ROW())) * ('종합'!$C$11:$H$15="초월++")), 0.04, 0))*C23} -> 0.1
A24: 저무는 달 | B24: =IF(COUNTIF('종합'!$B$11:$G$15, A24) > 0, TRUE, "") | C24: =IF('종합'!C3<=0, 0, IF('방어구룬'!B49=TRUE, IF('종합'!C3<=150, (3*FLOOR('종합'!C3/30,1)*(FLOOR('종합'!C3/30,1)-1) + 0.2*MOD('종합'!C3,30)*FLOOR('종합'!C3/30,1))/'종합'!C3, (60 + ('종합'!C3-150))/'종합'!C3), IF('종합'!C3<=300, (1.5*FLOOR('종합'!C3/30,1)*(FLOOR('종합'!C3/30,1)-1) + 0.1*MOD('종합'!C3,30)*FLOOR('종합'!C3/30,1))/'종합'!C3, (135 + ('종합'!C3-300))/'종합'!C3))) -> 0.15 | D24: {=0.06+IF(SUMPRODUCT(('종합'!$B$11:$G$15=INDIRECT("A"&ROW())) * ('종합'!$C$11:$H$15="초월+")), 0.02, 0)+IF(SUMPRODUCT(('종합'!$B$11:$G$15=INDIRECT("A"&ROW())) * ('종합'!$C$11:$H$15="초월++")), 0.04, 0)} -> 0.06 | E24: =0.2*C24 -> 0.03
A25: 땅울림 | B25: =IF(COUNTIF('종합'!$B$11:$G$15, A25) > 0, TRUE, "") | C25: 1 | D25: {=0.08+IF(SUMPRODUCT(('종합'!$B$11:$G$15=INDIRECT("A"&ROW())) * ('종합'!$C$11:$H$15="초월+")), 0.02, 0)+IF(SUMPRODUCT(('종합'!$B$11:$G$15=INDIRECT("A"&ROW())) * ('종합'!$C$11:$H$15="초월++")), 0.04, 0)} -> 0.08 | E25: =IF('종합'!C3<=0, 0, IF('종합'!C3<45, (0.03*FLOOR('종합'!C3/3,1)*(31-FLOOR('종합'!C3/3,1)) + ('종합'!C3-3*FLOOR('종합'!C3/3,1))*0.02*(15-FLOOR('종합'!C3/3,1)))/'종합'!C3, 7.2/'종합'!C3)) -> 0.06
A26: 신전기사 | B26: =IF(COUNTIF('종합'!$B$11:$G$15, A26) > 0, TRUE, "") | C26: 1 | J26: {=0.23+IF(SUMPRODUCT(('종합'!$B$11:$G$15=INDIRECT("A"&ROW())) * ('종합'!$C$11:$H$15="초월+")), 0.02, 0)+IF(SUMPRODUCT(('종합'!$B$11:$G$15=INDIRECT("A"&ROW())) * ('종합'!$C$11:$H$15="초월++")), 0.04, 0)} -> 0.23 | P26: {=IF('방어구룬'!B68, 0, -0.08+IF(SUMPRODUCT(('종합'!$B$11:$G$15=INDIRECT("A"&ROW())) * ('종합'!$C$11:$H$15="초월+")), 0.01, 0)+IF(SUMPRODUCT(('종합'!$B$11:$G$15=INDIRECT("A"&ROW())) * ('종합'!$C$11:$H$15="초월++")), 0.02, 0))} -> -0.08 | AA26: =IF('방어구룬'!B68, "", "결함") -> 결함
A27: 근위병+ | B27: =IF(COUNTIF('종합'!$B$11:$G$15, A27) > 0, TRUE, "") | C27: 1 | D27: {=0.23+IF(SUMPRODUCT(('종합'!$B$11:$G$15=INDIRECT("A"&ROW())) * ('종합'!$C$11:$H$15="초월+")), 0.02, 0)+IF(SUMPRODUCT(('종합'!$B$11:$G$15=INDIRECT("A"&ROW())) * ('종합'!$C$11:$H$15="초월++")), 0.04, 0)} -> 0.23 | S27: {=IF('방어구룬'!B68, 0, -0.07+IF(SUMPRODUCT(('종합'!$B$11:$G$15=INDIRECT("A"&ROW())) * ('종합'!$C$11:$H$15="초월+")), 0.01, 0)+IF(SUMPRODUCT(('종합'!$B$11:$G$15=INDIRECT("A"&ROW())) * ('종합'!$C$11:$H$15="초월++")), 0.02, 0))} -> -0.07 | AA27: =IF('방어구룬'!B68, "", "결함") -> 결함
A28: 침묵하는 산 | B28: =IF(COUNTIF('종합'!$B$11:$G$15, A28) > 0, TRUE, "") | C28: 0.1 | E28: {=(0.22+IF(SUMPRODUCT(('종합'!$B$11:$G$15=INDIRECT("A"&ROW())) * ('종합'!$C$11:$H$15="초월+")), 0.02, 0)+IF(SUMPRODUCT(('종합'!$B$11:$G$15=INDIRECT("A"&ROW())) * ('종합'!$C$11:$H$15="초월++")), 0.04, 0))*C28} -> 0.022
A29: 필사+ | B29: =IF(COUNTIF('종합'!$B$11:$G$15, A29) > 0, TRUE, "") | C29: 0.5 | D29: {=0.1+IF(SUMPRODUCT(('종합'!$B$11:$G$15=INDIRECT("A"&ROW())) * ('종합'!$C$11:$H$15="초월+")), 0.02, 0)+IF(SUMPRODUCT(('종합'!$B$11:$G$15=INDIRECT("A"&ROW())) * ('종합'!$C$11:$H$15="초월++")), 0.04, 0)} -> 0.1 | E29: =0.2*C29 -> 0.1
A30: 파멸+ | B30: =IF(COUNTIF('종합'!$B$11:$G$15, A30) > 0, TRUE, "") | C30: 1 | E30: {=0.25+IF(SUMPRODUCT(('종합'!$B$11:$G$15=INDIRECT("A"&ROW())) * ('종합'!$C$11:$H$15="초월+")), 0.02, 0)+IF(SUMPRODUCT(('종합'!$B$11:$G$15=INDIRECT("A"&ROW())) * ('종합'!$C$11:$H$15="초월++")), 0.04, 0)} -> 0.25 | AA30: 궁극기사용시20초동안
A31: 집정관 | B31: =IF(COUNTIF('종합'!$B$11:$G$15, A31) > 0, TRUE, "") | C31: 1 | F31: {=0.23+IF(SUMPRODUCT(('종합'!$B$11:$G$15=INDIRECT("A"&ROW())) * ('종합'!$C$11:$H$15="초월+")), 0.02, 0)+IF(SUMPRODUCT(('종합'!$B$11:$G$15=INDIRECT("A"&ROW())) * ('종합'!$C$11:$H$15="초월++")), 0.04, 0)} -> 0.23 | Q31: {=IF('방어구룬'!B68, 0, -0.08+IF(SUMPRODUCT(('종합'!$B$11:$G$15=INDIRECT("A"&ROW())) * ('종합'!$C$11:$H$15="초월+")), 0.01, 0)+IF(SUMPRODUCT(('종합'!$B$11:$G$15=INDIRECT("A"&ROW())) * ('종합'!$C$11:$H$15="초월++")), 0.03, 0))} -> -0.08
A32: 새벽별 | B32: =IF(COUNTIF('종합'!$B$11:$G$15, A32) > 0, TRUE, "") | C32: 1 | AA32: 조건부회속속도증가 | AB32: {=0.03+IF(SUMPRODUCT(('종합'!$B$11:$G$15=INDIRECT("A"&ROW())) * ('종합'!$C$11:$H$15="초월+")), 0.003, 0)+IF(SUMPRODUCT(('종합'!$B$11:$G$15=INDIRECT("A"&ROW())) * ('종합'!$C$11:$H$15="초월++")), 0.006, 0)} -> 0.03
A33: 눈 먼 예언자 | B33: =IF(COUNTIF('종합'!$B$11:$G$15, A33) > 0, TRUE, "") | C33: 1 | AA33: 각성재사용시간38초 | AB33: =IF(B33=TRUE, IF(SUMPRODUCT(('종합'!$B$11:$G$15=A33) * ('종합'!$C$11:$H$15="초월+")), 39, IF(SUMPRODUCT(('종합'!$B$11:$G$15=A33) * ('종합'!$C$11:$H$15="초월++")), 40, 38)), 0) -> 0
A34: 압도적인 힘 | B34: =IF(COUNTIF('종합'!$B$11:$G$15, A34) > 0, TRUE, "") -> TRUE | C34: =IF('방어구룬'!B33, ((FLOOR('종합'!C3/52,1) * 20) + MIN(MOD('종합'!C3,52), 20)) / '종합'!C3, ((FLOOR('종합'!C3/90,1) * 20) + MIN(MOD('종합'!C3,90), 20)) / '종합'!C3)*if('엠블럼룬'!AB$1="각성",1,0) -> 0.33333333 | D34: 0.06 | E34: {=(0.06+IF(SUMPRODUCT(('종합'!$B$11:$G$15=INDIRECT("A"&ROW())) * ('종합'!$C$11:$H$15="초월+")), 0.02, 0)+IF(SUMPRODUCT(('종합'!$B$11:$G$15=INDIRECT("A"&ROW())) * ('종합'!$C$11:$H$15="초월++")), 0.04, 0))*C34} -> 0.033333333 | H34: =0.06+(0.06*C34) -> 0.08 | P34: =0.04+(0.04*C34) -> 0.053333333 | AA34: 각성종속
A35: 섬세한 손놀림 | B35: =IF(COUNTIF('종합'!$B$11:$G$15, A35) > 0, TRUE, "") -> TRUE | C35: =IF('방어구룬'!B33, ((FLOOR('종합'!C3/52,1) * 20) + MIN(MOD('종합'!C3,52), 20)) / '종합'!C3, ((FLOOR('종합'!C3/90,1) * 20) + MIN(MOD('종합'!C3,90), 20)) / '종합'!C3)*if('엠블럼룬'!AB$1="각성",1,0) -> 0.33333333 | D35: 0.06 | E35: {=(0.06+IF(SUMPRODUCT(('종합'!$B$11:$G$15=INDIRECT("A"&ROW())) * ('종합'!$C$11:$H$15="초월+")), 0.02, 0)+IF(SUMPRODUCT(('종합'!$B$11:$G$15=INDIRECT("A"&ROW())) * ('종합'!$C$11:$H$15="초월++")), 0.04, 0))*C35} -> 0.033333333 | I35: =0.06+(0.06* C35) -> 0.08 | O35: =0.04+(0.04*C35) -> 0.053333333 | AA35: 각성종속
A36: 성역+ | B36: =IF(COUNTIF('종합'!$B$11:$G$15, A36) > 0, TRUE, "") | C36: 1 | D36: {=0.17+IF(SUMPRODUCT(('종합'!$B$11:$G$15=INDIRECT("A"&ROW())) * ('종합'!$C$11:$H$15="초월+")), 0.02, 0)+IF(SUMPRODUCT(('종합'!$B$11:$G$15=INDIRECT("A"&ROW())) * ('종합'!$C$11:$H$15="초월++")), 0.04, 0)} -> 0.17 | E36: =0.17*C36-0.17 -> 0
A37: 불안정한 힘 | B37: =IF(COUNTIF('종합'!$B$11:$G$15, A37) > 0, TRUE, "") | C37: 1 | F37: {=0.22+IF(SUMPRODUCT(('종합'!$B$11:$G$15=INDIRECT("A"&ROW())) * ('종합'!$C$11:$H$15="초월+")), 0.02, 0)+IF(SUMPRODUCT(('종합'!$B$11:$G$15=INDIRECT("A"&ROW())) * ('종합'!$C$11:$H$15="초월++")), 0.04, 0)} -> 0.22
A38: 고대 수호자 | B38: =IF(COUNTIF('종합'!$B$11:$G$15, A38) > 0, TRUE, "") | C38: 1 | D38: {=0.23+IF(SUMPRODUCT(('종합'!$B$11:$G$15=INDIRECT("A"&ROW())) * ('종합'!$C$11:$H$15="초월+")), 0.02, 0)+IF(SUMPRODUCT(('종합'!$B$11:$G$15=INDIRECT("A"&ROW())) * ('종합'!$C$11:$H$15="초월++")), 0.04, 0)} -> 0.23 | Z38: {=IF('방어구룬'!B68, 0, -0.08+IF(SUMPRODUCT(('종합'!$B$11:$G$15=INDIRECT("A"&ROW())) * ('종합'!$C$11:$H$15="초월+")), 0.01, 0))} -> -0.08
A39: 갈퀴발톱+ | B39: =IF(COUNTIF('종합'!$B$11:$G$15, A39) > 0, TRUE, "") | C39: 1 | R39: {=0.24+IF(SUMPRODUCT(('종합'!$B$11:$G$15=INDIRECT("A"&ROW())) * ('종합'!$C$11:$H$15="초월+")), 0.03, 0)+IF(SUMPRODUCT(('종합'!$B$11:$G$15=INDIRECT("A"&ROW())) * ('종합'!$C$11:$H$15="초월++")), 0.06, 0)} -> 0.24 | AA39: 2-1,444스피증0.24 | AB39: {=0.24+IF(SUMPRODUCT(('종합'!$B$11:$G$15=INDIRECT("A"&ROW())) * ('종합'!$C$11:$H$15="초월+")), 0.03, 0)+IF(SUMPRODUCT(('종합'!$B$11:$G$15=INDIRECT("A"&ROW())) * ('종합'!$C$11:$H$15="초월++")), 0.06, 0)} -> 0.24
A40: 태양 | B40: =IF(COUNTIF('종합'!$B$11:$G$15, A40) > 0, TRUE, "") | C40: 1 | X40: {=(0.89+IF(SUMPRODUCT(('종합'!$B$11:$G$15=INDIRECT("A"&ROW())) * ('종합'!$C$11:$H$15="초월+")), 0.09, 0)+IF(SUMPRODUCT(('종합'!$B$11:$G$15=INDIRECT("A"&ROW())) * ('종합'!$C$11:$H$15="초월++")), 0.18, 0))/(3.5/$C40)} -> 0.25428571 | AC40: 0.085
...

Sheet 엠블럼룬
A1: 엠블럼 룬 | B1: 사용여부 | C1: 가동률 | D1: 공증 | E1: 조건공증 | F1: 주피증 | G1: 받피증 | H1: 강타 | I1: 연타 | J1: 추피 | K1: 치피 | L1: 콤보피증 | M1: 멀티피증 | N1: 스킬피증 | O1: 추확 | P1: 치확 | Q1: 캐속 | R1: 무방 | S1: 재속 | T1: 스속 | U1: 공속 | V1: 공추 | W1: 궁획 | X1: 피해 | Y1: 지속피해 | Z1: 이속 | AA1: 특이사항 | AB1: =IFERROR(__xludf.DUMMYFUNCTION("FILTER(AB2:AB1000, B2:B1000=TRUE)"),"각성") -> 각성
A2: 현란함 | B2: =IF(COUNTIF('종합'!$B$11:$G$15, A2) > 0, TRUE, "") | C2: 1 | K2: 0.3 | P2: 0.1
A3: 지혜로움 | B3: =IF(COUNTIF('종합'!$B$11:$G$15, A3) > 0, TRUE, "") | C3: 1 | AA3: 쿨감18%
A4: 무자비한 포식자 | B4: =IF(COUNTIF('종합'!$B$11:$G$15, A4) > 0, TRUE, "") | C4: =((FLOOR('종합'!C3 / (90 - '방어구룬'!$AB$33),1) * 20) + MIN(MOD('종합'!C3, (90 - '방어구룬'!$AB$33)), 20)) / '종합'!C3 -> 0.33333333 | F4: {=0.21+IF(SUMPRODUCT(('종합'!$B$11:$G$15=INDIRECT("A"&ROW())) * ('종합'!$C$11:$H$15="초월+")), 0.02, 0)+(0.55*C4)} -> 0.39333333 | AA4: 무방비공격시 | AB4: 각성
A5: 순수한 힘 | B5: =IF(COUNTIF('종합'!$B$11:$G$15, A5) > 0, TRUE, "") | C5: =MAX(0, 30 - '스킬 및 딜사이클'!$Y$3)*'종합'!C5/'종합'!C3 -> 0.225 | F5: {=(0.27+IF(SUMPRODUCT(('종합'!$B$11:$G$15=INDIRECT("A"&ROW())) * ('종합'!$C$11:$H$15="초월+")), 0.02, 0))*C5} -> 0.06075 | W5: 0.2 | AA5: 궁극기사용시30초동안
A6: 부서진 하늘 | B6: =IF(COUNTIF('종합'!$B$11:$G$15, A6) > 0, TRUE, "") | C6: =((FLOOR('종합'!C3 / (90 - '방어구룬'!$AB$33),1) * 20) + MIN(MOD('종합'!C3, (90 - '방어구룬'!$AB$33)), 20)) / '종합'!C3 -> 0.33333333 | I6: {=0.08+IF(SUMPRODUCT(('종합'!$B$11:$G$15=INDIRECT("A"&ROW())) * ('종합'!$C$11:$H$15="초월+")), 0.02, 0)+(0.6*C6)} -> 0.28 | S6: {=0.08+IF(SUMPRODUCT(('종합'!$B$11:$G$15=INDIRECT("A"&ROW())) * ('종합'!$C$11:$H$15="초월+")), 0.02, 0)} -> 0.08 | X6: =(0.29/((1/('종합'!K39+'종합'!I40))/C6))*0.7 -> 0.040985499 | AB6: 각성
A7: 인도하는 빛 | B7: =IF(COUNTIF('종합'!$B$11:$G$15, A7) > 0, TRUE, "") | C7: =MAX(0, 15 - '스킬 및 딜사이클'!$Y$3)*'종합'!C5/'종합'!C3 -> 0 | E7: =0.08*C7 -> 0 | AA7: 궁극기사용시15초동안
A8: 대마법사 | B8: =IF(COUNTIF('종합'!$B$11:$G$15, A8) > 0, TRUE, "") | C8: =((FLOOR('종합'!C3 / (90 - '방어구룬'!$AB$33),1) * 20) + MIN(MOD('종합'!C3, (90 - '방어구룬'!$AB$33)), 20)) / '종합'!C3 -> 0.33333333 | E8: {=(0.45+IF(SUMPRODUCT(('종합'!$B$11:$G$15=INDIRECT("A"&ROW())) * ('종합'!$C$11:$H$15="초월+")), 0.1, 0))*C8} -> 0.15 | Q8: 0.14 | T8: =0.14+(0.25*C8) -> 0.22333333 | AA8: 차지1-1피해0.14 | AB8: 각성
A9: 흩날리는검 | B9: =IF(COUNTIF('종합'!$B$11:$G$15, A9) > 0, TRUE, "") | C9: =((FLOOR('종합'!C3 / (90 - '방어구룬'!$AB$33),1) * 35) + MIN(MOD('종합'!C3, (90 - '방어구룬'!$AB$33)), 35)) / '종합'!C3 -> 0.54166667 | E9: {=(0.35+IF(SUMPRODUCT(('종합'!$B$11:$G$15=INDIRECT("A"&ROW())) * ('종합'!$C$11:$H$15="초월+")), 0.1, 0))*C9} -> 0.18958333 | U9: =0.24+(0.2*C9) -> 0.34833333 | V9: =0.24+(0.2*C9) -> 0.34833333 | AB9: 각성
A10: 산맥 군주 | B10: =IF(COUNTIF('종합'!$B$11:$G$15, A10) > 0, TRUE, "") | C10: =((FLOOR('종합'!C3 / (90 - '방어구룬'!$AB$33),1) * 20) + MIN(MOD('종합'!C3, (90 - '방어구룬'!$AB$33)), 20)) / '종합'!C3 -> 0.33333333 | H10: {=0.08+IF(SUMPRODUCT(('종합'!$B$11:$G$15=INDIRECT("A"&ROW())) * ('종합'!$C$11:$H$15="초월+")), 0.02, 0)+IF(SUMPRODUCT(('종합'!$B$11:$G$15=INDIRECT("A"&ROW())) * ('종합'!$C$11:$H$15="초월++")), 0.02, 0)+((0.6+IF(SUMPRODUCT(('종합'!$B$11:$G$15=INDIRECT("A"&ROW())) * ('종합'!$C$11:$H$15="초월++")), 0.15, 0))*C10)} -> 0.28 | T10: {=0.08+IF(SUMPRODUCT(('종합'!$B$11:$G$15=INDIRECT("A"&ROW())) * ('종합'!$C$11:$H$15="초월+")), 0.02, 0)+IF(SUMPRODUCT(('종합'!$B$11:$G$15=INDIRECT("A"&ROW())) * ('종합'!$C$11:$H$15="초월++")), 0.02, 0)} -> 0.08 | X10: =1.55/(3/C10) -> 0.17222222 | AB10: 각성
A11: 아득한 빛 | B11: =IF(COUNTIF('종합'!$B$11:$G$15, A11) > 0, TRUE, "") -> TRUE | C11: =((FLOOR('종합'!C3 / (90 - '방어구룬'!$AB$33),1) * 20) + MIN(MOD('종합'!C3, (90 - '방어구룬'!$AB$33)), 20)) / '종합'!C3 -> 0.33333333 | F11: {=0.05+IF(SUMPRODUCT(('종합'!$B$11:$G$15=INDIRECT("A"&ROW())) * ('종합'!$C$11:$H$15="초월+")), 0.02, 0)+IF(SUMPRODUCT(('종합'!$B$11:$G$15=INDIRECT("A"&ROW())) * ('종합'!$C$11:$H$15="초월++")), 0.02, 0)} -> 0.07 | K11: {=0.1+((0.5+IF(SUMPRODUCT(('종합'!$B$11:$G$15=INDIRECT("A"&ROW())) * ('종합'!$C$11:$H$15="초월++")), 0.12, 0))*C11)} -> 0.30666667 | P11: =0.05+(0.2*C11) -> 0.11666667 | AB11: 각성
A12: 갈라진땅 | B12: =IF(COUNTIF('종합'!$B$11:$G$15, A12) > 0, TRUE, "") | C12: =((FLOOR('종합'!C3 / (90 - '방어구룬'!$AB$33),1) * 35) + MIN(MOD('종합'!C3, (90 - '방어구룬'!$AB$33)), 35)) / '종합'!C3 -> 0.54166667 | J12: {=(0.18+IF(SUMPRODUCT(('종합'!$B$11:$G$15=INDIRECT("A"&ROW())) * ('종합'!$C$11:$H$15="초월++")), 0.05, 0))*C12} -> 0.0975 | O12: {=0.12+IF(SUMPRODUCT(('종합'!$B$11:$G$15=INDIRECT("A"&ROW())) * ('종합'!$C$11:$H$15="초월+")), 0.02, 0)+IF(SUMPRODUCT(('종합'!$B$11:$G$15=INDIRECT("A"&ROW())) * ('종합'!$C$11:$H$15="초월++")), 0.02, 0)+(0.3*C12)} -> 0.2825 | AB12: 각성
A13: 빈값(엠블럼) | B13: =IF(COUNTIF('종합'!$B$11:$G$15, A13) > 0, TRUE, "")

Sheet 공격력변환
A1: 강화 | B1: 6성 | C1: 7성 | D1: 8성
F2: '종합'시트의 I4(공격력기본수치)를 입력할때 무기룬은 | I2: 8성 | J2: 이였으며 강화는 | K2: 18강 | L2: 이였습니다.
A3: 0강 | B3: 550 | C3: 628 | D3: 723 | F3: 7성 | G3: 무기룬 적용시 공격력기본수치를 알고싶습니다. | J3: ='종합'!I5 -> 27166 | K3: >>>>>>>>>>>> | L3: {=J3+(-INDEX(A:D, MATCH(K2, A:A, 0), MATCH(I2, 1:1, 0))+INDEX(A:D, MATCH(K2, A:A, 0), MATCH(F3, 1:1, 0)))*1.05} -> 26472.105 | M3: '종합'I5에 입력
A4: 1강 | B4: 707 | C4: 808 | D4: =C4/C3*D3 -> 930.2293 | L4: 정확한값이 아니라 근사값임
A5: 2강 | B5: 785 | C5: =B5/B4*C4 -> 897.14286 | D5: =C5/C4*D4 -> 1032.8571
A6: 3강 | B6: 825 | C6: =B6/B5*C5 -> 942.85714 | D6: =C6/C5*D5 -> 1085.4868
A7: 4강 | B7: 864 | C7: =B7/B6*C6 -> 987.42857 | D7: =C7/C6*D6 -> 1136.8007
A8: 5강 | B8: 903 | C8: =B8/B7*C7 -> 1032 | D8: =C8/C7*D7 -> 1188.1146
A9: 6강 | B9: 982 | C9: =B9/B8*C8 -> 1122.2857 | D9: =C9/C8*D8 -> 1292.0582
A10: 7강 | B10: 1060 | C10: =B10/B9*C9 -> 1211.4286 | D10: =C10/C9*D9 -> 1394.6861
A11: 8강 | B11: 1139 | C11: =B11/B10*C10 -> 1301.7143 | D11: =C11/C10*D10 -> 1498.6297
A12: 9강 | B12: 1217 | C12: =B12/B11*C11 -> 1390.8571 | D12: =C12/C11*D11 -> 1601.2575
A13: 10강 | B13: 1335 | C13: =B13/B12*C12 -> 1525.7143 | D13: =C13/C12*D12 -> 1756.515
A14: 11강 | B14: 1649 | C14: =B14/B13*C13 -> 1884.5714 | D14: =C14/C13*D13 -> 2169.6579
A15: 12강 | B15: 1963 | C15: =B15/B14*C14 -> 2243.4286 | D15: =C15/C14*D14 -> 2582.8007
A16: 13강 | B16: 2277 | C16: =B16/B15*C15 -> 2602.2857 | D16: =C16/C15*D15 -> 2995.9436
A17: 14강 | B17: 2591 | C17: =B17/B16*C16 -> 2961.1429 | D17: =C17/C16*D16 -> 3409.0864
A18: 15강 | B18: 2906 | C18: 3322 | D18: =C18/C17*D17 -> 3824.5318
A19: 16강 | B19: 3220 | C19: 3681 | D19: 4234
A20: 17강 | B20: 3534 | C20: =B20/B19*C19 -> 4039.9547 | D20: =C20/C19*D19 -> 4646.8807
A21: 18강 | B21: 3848 | C21: =B21/B20*C20 -> 4398.9093 | D21: =C21/C20*D20 -> 5059.7615
A22: 19강 | B22: 4162 | C22: =B22/B21*C21 -> 4757.864 | D22: =C22/C21*D21 -> 5472.6422

Sheet 스킬 및 딜사이클
A1: 스킬레벨 | B1: 0 | C1: ='종합'!B34 -> 10 | D1: 0 | E1: =C1 -> 10 | F1: 0 | G1: ='종합'!C34 -> 30 | H1: 0 | I1: =G1 -> 30 | J1: 0 | K1: ='종합'!D34 -> 10 | L1: 0 | M1: ='종합'!E34 -> 10 | N1: 0 | O1: =M1 -> 10 | P1: 0 | Q1: =M1 -> 10 | R1: 0 | S1: ='종합'!F34 -> 30 | T1: 0 | U1: =S1 -> 30 | V1: 0 | W1: =S1 -> 30
A2: 스킬이름 | B2: 1-1 | C2: 순정 | D2: 1-2 | E2: 순정 | F2: 2-1 | G2: 순정 | H2: 2-2 | I2: 순정 | J2: 3 | K2: 순정 | L2: 4-1 | M2: 순정 | N2: 4-2 | O2: 순정 | P2: 4-3 | Q2: 순정 | R2: 5-1 | S2: 순정 | T2: 5-2 | U2: 순정 | V2: 5-3 | W2: 순정 | X2: 6 | Y2: 궁극기 | AA2: 연타가동률
A3: 계수 | B3: 1.475 | C3: =B3*(1+0.03*C$1+0.02*((C$1>=2)+(C$1>=10)+(C$1>=15)+(C$1>=20)+(C$1>=30))) -> 1.9765 | D3: 0.81 | E3: =D3*(1+0.03*E$1+0.02*((E$1>=2)+(E$1>=10)+(E$1>=15)+(E$1>=20)+(E$1>=30))) -> 1.0854 | F3: 0.405 | G3: =F3*(1+0.03*G$1+0.02*((G$1>=2)+(G$1>=10)+(G$1>=15)+(G$1>=20)+(G$1>=30))) -> 0.81 | H3: 0.525 | I3: =H3*(1+0.03*I$1+0.02*((I$1>=2)+(I$1>=10)+(I$1>=15)+(I$1>=20)+(I$1>=30))) -> 1.05 | J3: 0.085 | K3: =J3*(1+0.03*K$1+0.02*((K$1>=2)+(K$1>=10)+(K$1>=15)+(K$1>=20)+(K$1>=30))) -> 0.1139 | L3: 0.141 | M3: =L3*(1+0.03*M$1+0.02*((M$1>=2)+(M$1>=10)+(M$1>=15)+(M$1>=20)+(M$1>=30))) -> 0.18894 | N3: 0.25 | O3: =N3*(1+0.03*O$1+0.02*((O$1>=2)+(O$1>=10)+(O$1>=15)+(O$1>=20)+(O$1>=30))) -> 0.335 | P3: 0.354 | Q3: =P3*(1+0.03*Q$1+0.02*((Q$1>=2)+(Q$1>=10)+(Q$1>=15)+(Q$1>=20)+(Q$1>=30))) -> 0.47436 | R3: 0.32 | S3: =R3*(1+0.03*S$1+0.02*((S$1>=2)+(S$1>=10)+(S$1>=15)+(S$1>=20)+(S$1>=30))) -> 0.64 | T3: 0.435 | U3: =T3*(1+0.03*U$1+0.02*((U$1>=2)+(U$1>=10)+(U$1>=15)+(U$1>=20)+(U$1>=30))) -> 0.87 | V3: 0.63 | W3: =V3*(1+0.03*W$1+0.02*((W$1>=2)+(W$1>=10)+(W$1>=15)+(W$1>=20)+(W$1>=30))) -> 1.26 | X3: 지속시간 | Y3: =9+0.25*'종합'!G34 -> 16.5 | AA3: =SUMIF('무기룬'!B:B, TRUE, '무기룬'!AC:AC) + SUMIF('방어구룬'!B:B, TRUE, '방어구룬'!AC:AC) + SUMIF('엠블럼룬'!B:B, TRUE, '엠블럼룬'!AC:AC) -> 0
B4: 0.825 | C4: =B4*(1+0.03*C$1+0.02*((C$1>=2)+(C$1>=10)+(C$1>=15)+(C$1>=20)+(C$1>=30))) -> 1.1055 | L4: 0.246 | M4: =L4*(1+0.03*M$1+0.02*((M$1>=2)+(M$1>=10)+(M$1>=15)+(M$1>=20)+(M$1>=30))) -> 0.32964 | N4: 0.437 | O4: =N4*(1+0.03*O$1+0.02*((O$1>=2)+(O$1>=10)+(O$1>=15)+(O$1>=20)+(O$1>=30))) -> 0.58558 | P4: 0.619 | Q4: =P4*(1+0.03*Q$1+0.02*((Q$1>=2)+(Q$1>=10)+(Q$1>=15)+(Q$1>=20)+(Q$1>=30))) -> 0.82946
B5: 1.15 | C5: =B5*(1+0.03*C$1+0.02*((C$1>=2)+(C$1>=10)+(C$1>=15)+(C$1>=20)+(C$1>=30))) -> 1.541 | M5: =L3*(1+0.03*M$1+0.02*((M$1>=2)+(M$1>=10)+(M$1>=15)+(M$1>=20)+(M$1>=30))) -> 0.18894 | O5: =N3*(1+0.03*O$1+0.02*((O$1>=2)+(O$1>=10)+(O$1>=15)+(O$1>=20)+(O$1>=30))) -> 0.335 | Q5: =P3*(1+0.03*Q$1+0.02*((Q$1>=2)+(Q$1>=10)+(Q$1>=15)+(Q$1>=20)+(Q$1>=30))) -> 0.47436
B6: 0.5 | C6: =B6*(1+0.03*C$1+0.02*((C$1>=2)+(C$1>=10)+(C$1>=15)+(C$1>=20)+(C$1>=30))) -> 0.67
A7: 쿨타임 | B7: 15 | F7: 14 | J7: 10 | L7: 15 | R7: 15
A8: 스킬이름 | B8: 1-1 | C8: 충돌 | D8: 1-2 | E8: 충돌 | F8: 2-1 | G8: 전진 | H8: 2-2 | I8: 전진 | J8: 3 | K8: 순발력 | L8: 4-1 | M8: 격파 | N8: 4-2 | O8: 격파 | P8: 4-3 | Q8: 격파 | R8: 5-1 | S8: 열혈 | T8: 5-2 | U8: 열혈 | V8: 5-3 | W8: 열혈
A9: 계수 | B9: 1.775 | C9: =B9*(1+0.03*C$1+0.02*((C$1>=2)+(C$1>=10)+(C$1>=15)+(C$1>=20)+(C$1>=30))) -> 2.3785 | D9: 0.81 | E9: =D9*(1+0.03*E$1+0.02*((E$1>=2)+(E$1>=10)+(E$1>=15)+(E$1>=20)+(E$1>=30))) -> 1.0854 | F9: 0.465 | G9: =F9*(1+0.03*G$1+0.02*((G$1>=2)+(G$1>=10)+(G$1>=15)+(G$1>=20)+(G$1>=30))) -> 0.93 | H9: 0.525 | I9: =H9*(1+0.03*I$1+0.02*((I$1>=2)+(I$1>=10)+(I$1>=15)+(I$1>=20)+(I$1>=30))) -> 1.05 | J9: 0.24 | K9: =J9*(1+0.03*K$1+0.02*((K$1>=2)+(K$1>=10)+(K$1>=15)+(K$1>=20)+(K$1>=30))) -> 0.3216 | L9: 0.188 | M9: =L9*(1+0.03*M$1+0.02*((M$1>=2)+(M$1>=10)+(M$1>=15)+(M$1>=20)+(M$1>=30))) -> 0.25192 | N9: 0.328 | O9: =N9*(1+0.03*O$1+0.02*((O$1>=2)+(O$1>=10)+(O$1>=15)+(O$1>=20)+(O$1>=30))) -> 0.43952 | P9: 0.468 | Q9: =P9*(1+0.03*Q$1+0.02*((Q$1>=2)+(Q$1>=10)+(Q$1>=15)+(Q$1>=20)+(Q$1>=30))) -> 0.62712 | R9: 0.435 | S9: =R9*(1+0.03*S$1+0.02*((S$1>=2)+(S$1>=10)+(S$1>=15)+(S$1>=20)+(S$1>=30))) -> 0.87 | T9: 0.6 | U9: =T9*(1+0.03*U$1+0.02*((U$1>=2)+(U$1>=10)+(U$1>=15)+(U$1>=20)+(U$1>=30))) -> 1.2 | V9: 0.86 | W9: =V9*(1+0.03*W$1+0.02*((W$1>=2)+(W$1>=10)+(W$1>=15)+(W$1>=20)+(W$1>=30))) -> 1.72
B10: 1.325 | C10: =B10*(1+0.03*C$1+0.02*((C$1>=2)+(C$1>=10)+(C$1>=15)+(C$1>=20)+(C$1>=30)))+0.35 -> 2.1255 | L10: 0.328 | M10: =L10*(1+0.03*M$1+0.02*((M$1>=2)+(M$1>=10)+(M$1>=15)+(M$1>=20)+(M$1>=30))) -> 0.43952 | N10: 0.574 | O10: =N10*(1+0.03*O$1+0.02*((O$1>=2)+(O$1>=10)+(O$1>=15)+(O$1>=20)+(O$1>=30))) -> 0.76916 | P10: 0.82 | Q10: =P10*(1+0.03*Q$1+0.02*((Q$1>=2)+(Q$1>=10)+(Q$1>=15)+(Q$1>=20)+(Q$1>=30))) -> 1.0988
B11: 1.7 | C11: =B11*(1+0.03*C$1+0.02*((C$1>=2)+(C$1>=10)+(C$1>=15)+(C$1>=20)+(C$1>=30)))+0.35 -> 2.628 | L11: 0.234 | M11: =L11*(1+0.03*M$1+0.02*((M$1>=2)+(M$1>=10)+(M$1>=15)+(M$1>=20)+(M$1>=30))) -> 0.31356 | N11: 0.41 | O11: =N11*(1+0.03*O$1+0.02*((O$1>=2)+(O$1>=10)+(O$1>=15)+(O$1>=20)+(O$1>=30))) -> 0.5494 | P11: 0.585 | Q11: =P11*(1+0.03*Q$1+0.02*((Q$1>=2)+(Q$1>=10)+(Q$1>=15)+(Q$1>=20)+(Q$1>=30))) -> 0.7839
B12: 0.94 | C12: =B12*(1+0.03*C$1+0.02*((C$1>=2)+(C$1>=10)+(C$1>=15)+(C$1>=20)+(C$1>=30)))+0.35 -> 1.6096 | L12: 0.1 | M12: =L12*(1+0.03*M$1+0.02*((M$1>=2)+(M$1>=10)+(M$1>=15)+(M$1>=20)+(M$1>=30))) -> 0.134 | N12: 0.1 | O12: =N12*(1+0.03*O$1+0.02*((O$1>=2)+(O$1>=10)+(O$1>=15)+(O$1>=20)+(O$1>=30))) -> 0.134 | P12: 0.1 | Q12: =P12*(1+0.03*Q$1+0.02*((Q$1>=2)+(Q$1>=10)+(Q$1>=15)+(Q$1>=20)+(Q$1>=30))) -> 0.134
A13: 쿨타임 | B13: 15 | F13: 14 | J13: 10 | L13: 15 | R13: 15
A14: 스킬이름 | B14: 1-1 | C14: 약점 | D14: 1-2 | E14: 약점 | R14: 5 | S14: 강격
A15: 계수 | B15: 0.92 | C15: =B15*(1+0.03*C$1+0.02*((C$1>=2)+(C$1>=10)+(C$1>=15)+(C$1>=20)+(C$1>=30))) -> 1.2328 | D15: 0.81 | E15: =D15*(1+0.03*E$1+0.02*((E$1>=2)+(E$1>=10)+(E$1>=15)+(E$1>=20)+(E$1>=30))) -> 1.0854 | R15: 1.615 | S15: =R15*(1+0.03*S$1+0.02*((S$1>=2)+(S$1>=10)+(S$1>=15)+(S$1>=20)+(S$1>=30))) -> 3.23
A19: 쿨타임 | B19: 15 | F19: 14 | J19: 10 | L19: 15 | R19: 13.6
C20: 강타 | E20: 강타 | G20: 강타 | I20: 강타 | K20: 이동 | M20: 강타 | O20: 강타 | Q20: 강타 | S20: 강타 | U20: 강타 | W20: 강타
C21: 이동 | E21: 방해 | G21: 이동 | I21: 이동 | K21: 생존 | M21: 보조 | O21: 보조 | Q21: 보조 | S21: 이동 | U21: 이동 | W21: 이동
C22: 방해 | G22: 방해 | K22: 보조
B23: =IFS(COUNTIF('종합'!C12:D14, "*충돌*")>0, "충돌", COUNTIF('종합'!C12:D14, "*약점*")>0, "약점", TRUE, "순정") -> 약점 | F23: =IF(COUNTIF('종합'!C12:D14, "*전진*")>0, "전진", "순정") -> 전진 | J23: =IF(COUNTIF('종합'!C12:D14, "*순발력*")>0, "순발력", "순정") -> 순정 | L23: =IF(COUNTIF('종합'!C12:D14, "*격파*")>0, "격파", "순정") -> 순정 | R23: =IFS(COUNTIF('종합'!C12:D14, "*열혈*")>0, "열혈", COUNTIF('종합'!C12:D14, "*강격*")>0, "강격", TRUE, "순정") -> 강격
A24: 계수 | B24: 1-1 | C24: {=XLOOKUP($B23, C2:C14, C3:C15)} -> 1.2328 | D24: 1-2 | E24: {=XLOOKUP($B23, E2:E14, E3:E15)} -> 1.0854 | F24: 2-1 | G24: {=XLOOKUP(F23, G2:G14, G3:G15)} -> 0.93 | H24: 2-2 | I24: {=XLOOKUP(F23, I2:I14, I3:I15)} -> 1.05 | J24: 3 | K24: {=XLOOKUP(J23, K2:K14, K3:K15)} -> 0.1139 | L24: 4-1 | M24: {=XLOOKUP(L23, M2:M14, M5:M17)} -> 0.18894 | N24: 4-2 | O24: {=XLOOKUP(L23, O2:O14, O5:O17)} -> 0.335 | P24: 4-3 | Q24: {=XLOOKUP(L23, Q2:Q14, Q5:Q17)} -> 0.47436 | R24: =IF(COUNTIF(R23, "강격")>0, "5", "5-1") -> 5 | S24: {=XLOOKUP($R23, S2:S14, S3:S15)} -> 3.23 | T24: =IF(COUNTIF(R23, "강격")>0, "", "5-2") | U24: {=XLOOKUP($R23, U2:U14, U3:U15)} -> #N/A | V24: =IF(COUNTIF(R23, "강격")>0, "", "5-3") | W24: {=XLOOKUP($R23, W2:W14, W3:W15)} -> #N/A
C25: {=XLOOKUP(B23, C2:C14, C6:C18)}
A26: 스킬속도 | B26: =IF(B23="약점", 1, 4) -> 1 | C26: =B26*(1-('종합'!$K$21+if(B23="약점",0,'종합'!K18))) -> 0.89584 | D26: 1.45 | E26: =D26*(1-'종합'!$K$21) -> 1.298968 | F26: 1 | G26: =F26*(1-'종합'!$K$21) -> 0.89584 | H26: 1.3 | I26: =H26*(1-'종합'!$K$21) -> 1.164592 | J26: 0.85 | K26: =J26*(1-'종합'!$K$21) -> 0.761464 | L26: 0.8 | M26: =L26*(1-'종합'!$K$21) -> 0.716672 | N26: 0.8 | O26: =N26*(1-'종합'!$K$21) -> 0.716672 | P26: 1.4 | Q26: =P26*(1-'종합'!$K$21) -> 1.254176 | R26: =IF(R23="강격", 1.4, 0.55) -> 1.4 | S26: =R26*(1-'종합'!$K$21) -> 1.254176 | T26: =IF(R23="강격", , 0.85) | U26: =T26*(1-'종합'!$K$21) -> 0 | V26: =IF(R23="강격", , 1.15) | W26: =V26*(1-'종합'!$K$21) -> 0
A27: 7e-05
A28: 쿨타임 | B28: {=XLOOKUP(B23, C2:C14, B7:B19)} -> 15 | C28: {=B28*(1-(SUM(MAP(C20:C22, LAMBDA(cell, SWITCH(cell, "강타", '종합'!$E$28, "이동", '종합'!$E$29, "보조", '종합'!$E$30, "방해", '종합'!$E$31, "생존", '종합'!$E$32, 0))))))*(if('엠블럼룬'!$B$3=true,0.82,1))*(1/(1+'종합'!K20))} -> 13.935 | F28: {=XLOOKUP(F23, G2:G14, F7:F19)} -> 14 | G28: {=F28*(1-(SUM(MAP(G20:G22, LAMBDA(cell, SWITCH(cell, "강타", '종합'!$E$28, "이동", '종합'!$E$29, "보조", '종합'!$E$30, "방해", '종합'!$E$31, "생존", '종합'!$E$32, 0))))))*(if('엠블럼룬'!$B$3=true,0.82,1))*(1/(1+'종합'!$K$20))} -> 13.006 | J28: {=XLOOKUP(J23, K2:K14, J7:J19)} -> 10 | K28: {=J28*(1-(SUM(MAP(K20:K22, LAMBDA(cell, SWITCH(cell, "강타", '종합'!$E$28, "이동", '종합'!$E$29, "보조", '종합'!$E$30, "방해", '종합'!$E$31, "생존", '종합'!$E$32, 0))))))*(if('엠블럼룬'!$B$3=true,0.82,1))*(1/(1+'종합'!$K$20))} -> 9.5 | L28: {=XLOOKUP(L23, M2:M14, L7:L19)} -> 15 | M28: {=L28*(1-(SUM(MAP(M20:M22, LAMBDA(cell, SWITCH(cell, "강타", '종합'!$E$28, "이동", '종합'!$E$29, "보조", '종합'!$E$30, "방해", '종합'!$E$31, "생존", '종합'!$E$32, 0))))))*(if('엠블럼룬'!$B$3=true,0.82,1))*(1/(1+'종합'!$K$20))} -> 14.46 | R28: {=XLOOKUP(R23, S2:S14, R7:R19)} -> 13.6 | S28: {=R28*(1-(SUM(MAP(S20:S22, LAMBDA(cell, SWITCH(cell, "강타", '종합'!$E$28, "이동", '종합'!$E$29, "보조", '종합'!$E$30, "방해", '종합'!$E$31, "생존", '종합'!$E$32, 0))))))*(if('엠블럼룬'!$B$3=true,0.82,1))*(1/(1+'종합'!$K$20))} -> 12.6344 | AB28: 1-1 스킬쿨 세공 지혜합연산 | AF28: {=B28*(1-((SUM(MAP(C20:C22, LAMBDA(cell, SWITCH(cell, "강타", '종합'!$E$28, "이동", '종합'!$E$29, "보조", '종합'!$E$30, "방해", '종합'!$E$31, "생존", '종합'!$E$32, 0)))))+(if('엠블럼룬'!$B$3=true,0.18,0))))*(1/(1+'종합'!K20))} -> 13.935
